Workbook
Name \a: #REF!
Name \c: #REF!
Name \D: #REF!
Name \e: #REF!
Name \f: #REF!
Name \i: #REF!
Name \l: #REF!
Name \m: #REF!
Name \o: #N/A
Name \P: #REF!
Name \QQ: #REF!
Name \s: #REF!
Name \v: #REF!
Name \w: #REF!
Name \zsfh.zdvsxb: #REF!
Name _: #REF!
Name __________________________________________________________________________cto2: #REF!
Name __________________________________________________________________________er1: #REF!
Name __________________________________________________________________________rr2: #REF!
Name _________________________________________________rev2: #REF!
Name ____________________________________________alt2: #REF!
Name ____________________________________________R: #REF!
Name ____________________________________________rr2: #REF!
Name ___________________________________________alt2: #REF!
Name ___________________________________________bh1: #N/A
Name ___________________________________________bh2: #N/A
Name ___________________________________________bh3: #N/A
Name ___________________________________________bh4: #N/A
Name ___________________________________________bh5: #N/A
Name ___________________________________________bh6: #N/A
Name ___________________________________________bh7: #N/A
Name ___________________________________________bh8: #N/A
Name ___________________________________________bh9: #N/A
Name ___________________________________________Brz1: #REF!
Name ___________________________________________Brz2: #REF!
Name ___________________________________________R: #REF!
Name ___________________________________________rio1: #N/A
Name ___________________________________________rio2: #N/A
Name ___________________________________________rio3: #N/A
Name ___________________________________________rj1: #N/A
Name ___________________________________________rj2: #N/A
Name ___________________________________________rj3: #N/A
Name ___________________________________________rj4: #N/A
Name ___________________________________________rj5: #N/A
Name ___________________________________________rj6: #N/A
Name ___________________________________________rj7: #N/A
Name ___________________________________________rj8: #N/A
Name ___________________________________________rj9: #N/A
Name ___________________________________________rr2: #REF!
Name ___________________________________________rs2: #N/A
Name ___________________________________________rs3: #N/A
Name ___________________________________________rs4: #N/A
Name ___________________________________________rs5: #N/A
Name ___________________________________________rs6: #N/A
Name ___________________________________________rs7: #N/A
Name ___________________________________________rs8: #N/A
Name ___________________________________________rs9: #N/A
Name ___________________________________________sc2: #N/A
Name ___________________________________________sc3: #N/A
Name ___________________________________________sc4: #N/A

Sheet RESUMO VEÍCULOS
A6: BOTICÁRIO REGIONAL - IVESTIMENTO ESTIMADO PROJETO OOH 2025
A7: Resumo de investimento previsto por empresa/capital
CL8: TT NORTE | CM8: TT SUDESTE | CN8: TT CENTRO OESTE | CO8: TT SUL | CP8: TT NORDESTE | CQ8: TT BRASIL
A9: PRAÇA | B9: ELETROMIDIA | C9: CLEAR CHANNEL | D9: JCDECAUX | E9: WEOOH | F9: BME | G9: ULTRA OOH | H9: VSP | I9: THE VOICE | J9: GREEN OOH | K9: S2X | L9: PRISMA OOH | M9: TC | N9: PURAKA | O9: BUREAU | P9: KALLAS | Q9: M2 | R9: TELAS PROMO | S9: WVK | T9: ATOS | U9: TOCANTINS | V9: LED+ | W9: ARTES | X9: ATUAL | Y9: CENTER | Z9: MAELY | AA9: PONTO | AB9: SPEEDY | AC9: ITABUS | AD9: NEOOH | AE9: RZK | AF9: MOVIE MIDIA | AG9: PAD | AH9: FREDZAK | AI9: URBANA | AJ9: FLY | AK9: TUTTO | AL9: CARREGA+ | AM9: MUDE | AN9: ADVER | AO9: CRIATIVA | AP9: ALTO IMPACTO | AQ9: METROPOLLIS | AR9: VISUPLAC | AS9: SPEED | AT9: CUIABÁ | AU9: TC | AV9: TOTAL | AW9: TOP | AX9: ZOOM | AY9: CAPITAL | AZ9: VISÃO | BA9: LETS FLY | BB9: FENIX | BC9: CRIATIVA | BD9: SINERGY | BE9: PONTO Z | BF9: OUTDOOR MIDIA | BG9: FAVRETTO | BH9: RPO | BI9: ATIVA | BJ9: HMIDIA | BK9: IMOBI | BL9: SUPERLUX | BM9: MURAL | BN9: BANDEIRANTES | BO9: ROTA | BP9: RIO VERDE | BQ9: TREND | BR9: URBANA | BS9: CITY OUTDOOR | BT9: PALMER | BU9: PANDA | BV9: PANORAMA | BW9: COMPASSO | BX9: STAMPA | BY9: EXIBA | BZ9: MUDE | CA9: BIGDOOH | CB9: CONSTRUMIDIA | CC9: LINHARES | CD9: OUTLIGHT | CE9: IMPACTO | CF9: MIDIA BUS | CG9: ROTA 66 | CH9: C. DE MIDIA | CI9: IMAGEM | CJ9: MURAL | CK9: WAY | CL9: =CL10/$CQ$10 -> #REF! | CM9: =CM10/$CQ$10 -> #REF! | CN9: =CN10/$CQ$10 -> #REF! | CO9: =CO10/$CQ$10 -> #REF! | CP9: =CP10/$CQ$10 -> #REF! | CQ9: =SUM(CL9:CP9) -> #REF!
CL10: =SUM(CL12:CL64) -> 6095465.4 | CM10: =SUM(CM12:CM64) -> 30461982 | CN10: =SUM(CN12:CN64) -> 10222355 | CO10: =SUM(CO12:CO64) -> 7952437.9 | CP10: =SUM(CP12:CP64) -> #REF! | CQ10: =SUM(CL10:CP10) -> #REF!
A11: BELEM | B11: ELETROMIDIA | D11: JCDECAUX | E11: WEOOH | F11: BME | G11: ULTRA OOH | J11: GREEN OOH | K11: S2X | L11: PRISMA OOH | N11: PURAKA | O11: BUREAU | P11: KALLAS
A12: R$ | B12: 7114.8 | E12: 60804.337 | F12: 520920 | G12: 346410.75 | J12: 379756.8 | K12: 137376 | L12: 77220 | N12: 231540 | O12: 489423.45 | P12: 24000 | CL12: =SUM(A12:CK12) -> 2274566.1
A13: BOA VISTA | P13: KALLAS | Q13: M2 | R13: TELAS PROMO
A14: R$ | P14: 8640 | Q14: 68096 | R14: 194400 | CL14: =SUM(A14:CK14) -> 271136
A15: MACAPA | O15: BUREAU | T15: ATOS
A16: R$ | O16: 149840 | T16: 246400 | CL16: =SUM(A16:CK16) -> 396240
A17: MANAUS | E17: WEOOH | F17: BME | H17: VSP | I17: THE VOICE | K17: S2X | N17: PURAKA | O17: BUREAU | S17: WVK
A18: R$ | E18: 95072.373 | F18: 428310 | H18: 51425 | I18: 175582.8 | K18: 29256 | N18: 335610 | O18: 256185 | S18: 402186.72 | CL18: =SUM(A18:CK18) -> 1773627.9
A19: PALMAS | K19: SX2 | O19: BUREAU | P19: KALLAS | U19: TOCANTINS | V19: LED+ | W19: ARTES
A20: R$ | K20: 20352 | O20: 93840 | P20: 8640 | U20: 270900 | V20: 57093.75 | W20: 99825 | CL20: =SUM(A20:CK20) -> 550650.75
A21: PORTO VELHO | K21: S2X | P21: KALLAS | Q21: M2
A22: R$ | K22: 30528 | P22: 7200 | Q22: 475635 | CL22: =SUM(A22:CK22) -> 513363
A23: RIO BRANCO | K23: SX2 | O23: BUREAU | P23: KALLAS | X23: ATUAL | Y23: CENTER
A24: R$ | K24: 17203.2 | O24: 23840 | P24: 4800 | X24: 214838.4 | Y24: 55200 | CL24: =SUM(A24:CK24) -> 315881.6
A25: VITORIA | C25: CLEAR CHANNEL | P25: KALLAS | Z25: MAELY | AA25: PONTO | AB25: SPEEDY
A26: R$ | C26: 128700 | P26: 232544 | Z26: 232554 | AA26: 305676.8 | AB26: 80352 | CM26: =SUM(B26:CK26) -> 979826.8
A27: SAO PAULO | B27: ELETROMIDIA | D27: JCDECAUX | AC27: ITABUS | AD27: NEOOH | AE27: RZK
A28: R$ | B28: 2971385.3 | D28: 12686831 | AC28: 2867873.5 | AD28: 877457 | AE28: 756000 | CM28: =SUM(B28:CK28) -> 20159547
A29: BELO HORIZONTE | P29: KALLAS | AF29: MOVIE MIDIA | AG29: PAD | AH29: FREDZAK | AI29: URBANA | AJ29: FLY | AK29: TUTTO | AL29: CARREGA+
A30: R$ | P30: 12000 | AF30: 1295910 | AG30: 214053.12 | AH30: 289710.24 | AI30: 1541629 | AJ30: 183700 | AK30: 125442 | AL30: 59141.34 | CM30: =SUM(B30:CK30) -> 3721585.7
A31: RIO DE JANEIRO | C31: CLEAR CHANNEL | D31: JCDECAUX | P31: KALLAS | AF31: MOVIE MIDIA | AK31: TUTTO | AM31: MUDE | AN31: ADVER | AO31: CRIATIVA | AP31: ALTO IMPACTO
A32: R$ | C32: 1020895.2 | D32: 436363.2 | P32: 518400 | AF32: 2052288 | AK32: 134172 | AM32: 592900 | AN32: 390540 | AO32: 222700 | AP32: 232764 | CM32: =SUM(B32:CK32) -> 5601022.4
A33: BRASILIA | D33: JCDECAUX | E33: WEOOH | AD33: NEOOH | AQ33: METROPOLIS | AR33: VISUPLAC
A34: R$ | D34: 67737.6 | E34: 736007.7 | AD34: 95040 | AQ34: 518820 | AR34: 787010 | CN34: =SUM(B34:CK34) -> 2204615.3
A35: CUIABA | E35: WEOOH | M35: TC | P35: KALLAS | AK35: TUTTO | AS35: SPEED | AT35: CUIABÁ | AU35: TC
A36: R$ | E36: 202681.13 | M36: 664022.5 | P36: 24000 | AK36: 192681 | AS36: 355205 | AT36: 694663 | AU36: 664022.5 | CN36: =SUM(B36:CK36) -> 2797275.1
A37: CAMPO GRANDE | E37: WEOOH | P37: KALLAS | AK37: TUTTO | AV37: TOTAL | AW37: TOP | AX37: ZOOM
A38: R$ | E38: 650174.04 | P38: 16800 | AK38: 49356 | AV38: 558356 | AW38: 288000 | AX38: 192178.5 | CN38: =SUM(B38:CK38) -> 1754864.5
A39: GOIANIA | E39: WEOOH | P39: KALLAS | AK39: TUTTO | AL39: CARREGA+ | AM39: MUDE | AY39: CAPITAL | AZ39: VISAO | BA39: LETS FLY | BB39: FENIX
A40: R$ | E40: 56752.5 | P40: 65717.5 | AK40: 191515.2 | AL40: 125125.56 | AM40: 443528 | AY40: 1173151.9 | AZ40: 507000 | BA40: 385940 | BB40: 516869.7 | CN40: =SUM(B40:CK40) -> 3465600.4
A41: FLORIAMOPOLIS | P41: KALLAS | BC41: CRIATIVA SUL | BD41: SINERGY | BE41: PONTO Z
A42: R$ | P42: 254100 | BC42: 645022.5 | BD42: 940995 | BE42: 184144.95 | CO42: =SUM(B42:CK42) -> 2024262.4
A43: CURITIBA | C43: CLEAR CHANNEL | BD43: SINERGY | BF43: OUTDOOR MIDIA | BG43: FAVRETTO | BH43: RPO
A44: R$ | C44: 667590 | BD44: 386595 | BF44: 1688272.3 | BG44: 209169 | BH44: 52200 | CO44: =SUM(B44:CK44) -> 3003826.3
A45: PORTO ALEGRE | C45: CLEAR | AK45: TUTTO | BD45: SINERGY | BI45: ATIVA | BJ45: HMIDIA | BK45: IMOBI
...

Sheet BELEM
A1: =[13]BASE!A2 -> ESTUDO BELEM
A2: IBGE 2024/ CENSO 2022
A7: INVESTIMENTO BELEM CAPITAL OOH 2024 | B7: 1641632.8
A8: INVESTIMENTO PARÁ OOH 2024 | B8: 2328715
A10: R$ BRUTO BELÉM CAPITAL - 2025 OOH | B10: 3295226.5
A11: BUDGET BRUTO PARÁ - 2025 OOH (100%) | B11: 4453008.8
A14: Exclusão de Bronze
A15: CICLOS/MEDALHAS | C15: % BUDGET/CICLO | D15: R$ MEDALHA | E15: R$ UNIT. MEDALHAS
A16: Datas | B16: 3 - 2 produto/1 promo | C16: 0.37 | D16: 1219233.8 | E16: 406411.27
A17: Ouro | B17: 5 - 4 produto/ 1 promo | C17: 0.4 | D17: 1318090.6 | E17: 329522.65
A18: Prata | B18: 3 | C18: 0.23 | D18: 757902.09 | E18: 189475.52
B19: 11 ciclos | C19: 1
A21: População Target - AS ABC 18/49 | B21: 584877
A22: Popuação Capital - 1.1303.403 | B22: 1103403
E24: Cobertura total - Data Produto | F24: 70% | H24: Cobertura total - Data Promo | J24: 0.73
E25: Frequencia | F25: 39 | H25: Frequencia | J25: 42
E26: TRP | F26: 2.623 | H26: TRP | J26: 3042
E27: OTS | F27: 15.338.810 | H27: OTS | J27: 17791934
A29: Programação - Ciclo Data Produto
A31: 1 CICLO | S31: TOTAL ANO / CLUSTER
A32: Praça | B32: Exibidores | C32: Pen/Aff | D32: Canais | E32: Formato | F32: Range de volume ideal | G32: Qtdade | H32: Periodicidade | I32: Mês Base | M32: TT | N32: R$ Unit Bruto | O32: Desconto | P32: R$ Unit Bruto | Q32: R$ TT Bruto | R32: % | S32: R$ Total | T32: AMBIENTES | Y32: FORMATO | AB32: EMPRESAS
I33: S1 | J33: S2 | K33: S3 | L33: S4 | M33: Flight | N33: Tabela | O33: (%) | P33: Negociado | Q33: Negociado | S33: ano
A34: DATAS MÃES/NATAL | T34: GDES | U34: MUB | V34: TRANSP | W34: AERO | X34: OPORT | Y34: ESTÁTICO | Z34: DIGITAL | AB34: ELETROMIDIA | AC34: WEOOH | AD34: BME | AE34: ULTRA OOH | AF34: GREEN OOH | AG34: S2X | AH34: PRISMA OOH | AI34: PURAKA | AJ34: BUREAU | AK34: KALLAS
A36: Belem - PA | B36: Eletromidia | C36: 50/156 | D36: Painel de Led | E36: Digital | F36: 6/12 | G36: 1 | H36: Semanal | I36: 1 | K36: 1 | M36: 1 | N36: 5929 | O36: 0.6 | P36: =N36*(1-O36) -> 2371.6 | Q36: =P36*M36*G36 -> 2371.6 | R36: =Q36/$Q$59 -> 0.0058381117 | S36: =Q36*2 -> 4743.2 | T36: =S36 -> 4743.2 | Z36: =S36 -> 4743.2 | AB36: =S36 -> 4743.2
A37: Belem - PA | B37: WeOOH | C37: 50/156 | D37: Painel de Led | E37: Digital | F37: 6/12 | G37: 1 | H37: Mensal | I37: 1 | M37: 1 | N37: 27024.15 | O37: 0.75 | P37: =N37*(1-O37) -> 6756.0375 | Q37: =P37*M37*G37 -> 6756.0375 | R37: =Q37/$Q$59 -> 0.016631178 | S37: =Q37*2 -> 13512.075 | T37: =S37 -> 13512.075 | Z37: =S37 -> 13512.075 | AC37: =S37 -> 13512.075
A38: Belem - PA | B38: Brasil Midia Exterior | C38: 50/156 | D38: Painel de Led | E38: Digital | F38: 6/12 | G38: 1 | H38: Mensal | I38: 1 | M38: 1 | N38: 7000 | O38: 0.1 | P38: =N38*(1-O38) -> 6300 | Q38: =P38*M38*G38 -> 6300 | R38: =Q38/$Q$59 -> 0.015508561 | S38: =Q38*2 -> 12600 | T38: =S38 -> 12600 | Z38: =S38 -> 12600 | AD38: =S38 -> 12600
A39: Belem - PA | B39: Brasil Midia Exterior | C39: 50/156 | D39: Frontlight | E39: Estático | F39: 4/8 | G39: 1 | H39: Mensal | I39: 1 | M39: 1 | N39: 7500 | O39: 0.1 | P39: =N39*(1-O39) -> 6750 | Q39: =P39*M39*G39 -> 6750 | R39: =Q39/$Q$59 -> 0.016616316 | S39: =Q39*2 -> 13500 | T39: =S39 -> 13500 | Y39: =S39 -> 13500 | AD39: =S39 -> 13500
A40: Belem - PA | B40: Brasil Midia Exterior | C40: 50/156 | D40: Outdoor lonado | E40: Estático | F40: 15/30 | G40: 25 | H40: Mensal | I40: 25 | M40: 1 | N40: 2650 | O40: 0.1 | P40: =N40*(1-O40) -> 2385 | Q40: =P40*M40*G40 -> 59625 | R40: =Q40/$Q$59 -> 0.14677745 | S40: =Q40*2 -> 119250 | T40: =S40 -> 119250 | Y40: =S40 -> 119250 | AD40: =S40 -> 119250
A41: Belem - PA | B41: Ultra OOH | C41: 50/156 | D41: Painel de Led | E41: Digital | F41: 6/12 | G41: 1 | H41: Mensal | I41: 1 | M41: 1 | N41: 5593 | O41: 0.25 | P41: =N41*(1-O41) -> 4194.75 | Q41: =P41*M41*G41 -> 4194.75 | R41: =Q41/$Q$59 -> 0.010326117 | S41: =Q41*2 -> 8389.5 | T41: =S41 -> 8389.5 | Z41: =S41 -> 8389.5 | AE41: =S41 -> 8389.5
A42: Belem - PA | B42: Ultra OOH | C42: 50/156 | D42: Frontlight | E42: Estático | F42: 4/8 | G42: 2 | H42: Mensal | I42: 2 | M42: 1 | N42: =(10000+6680)/2 -> 8340 | O42: 0.3 | P42: =N42*(1-O42) -> 5838 | Q42: =P42*M42*G42 -> 11676 | R42: =Q42/$Q$59 -> 0.028742534 | S42: =Q42*2 -> 23352 | T42: =S42 -> 23352 | Y42: =S42 -> 23352 | AE42: =S42 -> 23352
A43: Belem - PA | B43: Ultra OOH | C43: 50/156 | D43: Empena | E43: Estático | F43: 2/5 | G43: 3 | H43: Mensal | I43: 3 | M43: 1 | N43: =(13400+28000+16000)/3 -> 19133.333 | O43: 0.25 | P43: =N43*(1-O43) -> 14350 | Q43: =P43*M43*G43 -> 43050 | R43: =Q43/$Q$59 -> 0.10597517 | S43: =Q43*2 -> 86100 | T43: =S43 -> 86100 | Y43: =S43 -> 86100 | AE43: =S43 -> 86100
A44: Belem - PA | B44: Green Outdoor | C44: 50/156 | D44: Painel de Led | E44: Digital | F44: 6/12 | G44: 1 | H44: Mensal | I44: 1 | M44: 1 | N44: 2362 | O44: 0.2 | P44: =N44*(1-O44) -> 1889.6 | Q44: =P44*M44*G44 -> 1889.6 | R44: =Q44/$Q$59 -> 0.0046515837 | S44: =Q44*2 -> 3779.2 | T44: =S44 -> 3779.2 | Z44: =S44 -> 3779.2 | AF44: =S44 -> 3779.2
A45: Belem - PA | B45: Green Outdoor | C45: 50/156 | D45: Outdoor lonado | E45: Estática | F45: 15/30 | G45: 25 | H45: Mensal | K45: 25 | M45: 1 | N45: 2650 | O45: 0.2 | P45: =N45*(1-O45) -> 2120 | Q45: =P45*M45*G45 -> 53000 | R45: =Q45/$Q$59 -> 0.13046885 | S45: =Q45*2 -> 106000 | T45: =S45 -> 106000 | Y45: =S45 -> 106000 | AF45: =S45 -> 106000
A46: Belem - PA | B46: S2X Promoções | C46: 30/155 | D46: Carro de Som | E46: Som | F46: 7/30 | G46: 7 | H46: Diaria 8 horas | I46: 7 | K46: 7 | M46: 2 | N46: =265*8 -> 2120 | O46: 0.4 | P46: =N46*(1-O46) -> 1272 | Q46: =P46*M46*G46 -> 17808 | R46: =Q46/$Q$59 -> 0.043837533 | S46: =Q46*2 -> 35616 | T46: =S46 -> 35616 | AG46: =S46 -> 35616
A47: Belem - PA | B47: Prisma OOH | C47: 50/156 | D47: Painel de Led | E47: Digital | F47: 6/12 | G47: 2 | H47: Mensal | I47: 2 | M47: 1 | N47: 7920 | O47: 0.25 | P47: =N47*(1-O47) -> 5940 | Q47: =P47*M47*G47 -> 11880 | R47: =Q47/$Q$59 -> 0.029244716 | S47: =Q47*2 -> 23760 | T47: =S47 -> 23760 | Z47: =S47 -> 23760 | AH47: =S47 -> 23760
A48: Belem - PA | B48: Puraka | C48: 50/156 | D48: Painel de Led | E48: Digital | F48: 6/12 | G48: 2 | H48: Mensal | I48: 2 | M48: 1 | N48: 18500 | O48: 0.6 | P48: =N48*(1-O48) -> 7400 | Q48: =P48*M48*G48 -> 14800 | R48: =Q48/$Q$59 -> 0.036432811 | S48: =Q48*2 -> 29600 | T48: =S48 -> 29600 | Z48: =S48 -> 29600 | AI48: =S48 -> 29600
A49: Belem - PA | B49: Puraka | C49: 50/156 | D49: Frontlight | E49: Estático | F49: 4/8 | G49: 2 | H49: Mensal | I49: 2 | M49: 1 | N49: 20500 | O49: 0.58 | P49: =N49*(1-O49) -> 8610 | Q49: =P49*M49*G49 -> 17220 | R49: =Q49/$Q$59 -> 0.042390067 | S49: =Q49*2 -> 34440 | T49: =S49 -> 34440 | Y49: =S49 -> 34440 | AI49: =S49 -> 34440
A50: Belem - PA | B50: Bureau de Mídia | C50: 50/156 | D50: Painel de Led | E50: Digital | F50: 6/12 | G50: 1 | H50: Mensal | I50: 1 | M50: 1 | N50: 8125 | O50: 0.15 | P50: =N50*(1-O50) -> 6906.25 | Q50: =P50*M50*G50 -> 6906.25 | R50: =Q50/$Q$59 -> 0.017000953 | S50: =Q50*2 -> 13812.5 | T50: =S50 -> 13812.5 | Z50: =S50 -> 13812.5 | AJ50: =S50 -> 13812.5
A51: Belem - PA | B51: Bureau de Mídia | C51: 50/156 | D51: Envelopamento Barco | E51: Estático | F51: 1 | G51: 1 | H51: Mensal | I51: 1 | M51: 1 | N51: 73000 | O51: 0 | P51: =N51*(1-O51) -> 73000 | Q51: =P51*M51*G51 -> 73000 | R51: =Q51/$Q$59 -> 0.17970238 | S51: =Q51*2 -> 146000 | V51: =S51 -> 146000 | Z51: =S51 -> 146000 | AJ51: =S51 -> 146000
A56: Belem - PA | B56: Aeroporto | S56: =Q56*2 -> 0 | W56: =S56 -> 0
...

Sheet BELEM PLAN
A1: ciclos | B1: regional_boticario | C1: uf | D1: praca | E1: exibidores | F1: formato | G1: circuito | H1: avulso | I1: ranking | J1: pesos | K1: estatico | L1: digital | M1: range_minimo | N1: range_maximo | O1: quantidade | P1: periodicidade | Q1: s1 | R1: s2 | S1: s3 | T1: s4 | U1: flight | V1: unitario_bruto_tabela | W1: desconto | X1: unitario_bruto_negociado | Y1: total_bruto_negociado
A2: data produto | B2: norte | C2: pa | D2: belem | E2: eletromidia | F2: Painel de Led | H2: X | I2: 2 | L2: X | M2: 6 | N2: 12 | O2: 1 | P2: semanal | Q2: 1 | S2: 1 | U2: 2 | V2: 5929 | W2: 0.6 | X2: =V2*(1-W2) -> 2371.6 | Y2: =X2*U2*O2 -> 4743.2
A3: data produto | B3: norte | C3: pa | D3: belem | E3: WeOOH | F3: Painel de Led | H3: X | I3: 2 | L3: X | M3: 6 | N3: 12 | O3: 1 | P3: Mensal | Q3: 1 | U3: 1 | V3: 27024.1 | W3: 0.75 | X3: =V3*(1-W3) -> 6756.025 | Y3: =X3*U3*O3 -> 6756.025
A4: data produto | B4: norte | C4: pa | D4: belem | E4: Brasil Midia Exterior | F4: Painel de Led | H4: X | I4: 2 | L4: X | M4: 6 | N4: 12 | O4: 1 | P4: Mensal | Q4: 1 | U4: 1 | V4: 7000 | W4: 0.1 | X4: =V4*(1-W4) -> 6300 | Y4: =X4*U4*O4 -> 6300
A5: data produto | B5: norte | C5: pa | D5: belem | E5: Brasil Midia Exterior | F5: Frontlight | H5: X | I5: 5 | K5: X | M5: 4 | N5: 8 | O5: 1 | P5: Mensal | Q5: 1 | U5: 1 | V5: 7500 | W5: 0.1 | X5: =V5*(1-W5) -> 6750 | Y5: =X5*U5*O5 -> 6750
A6: data produto | B6: norte | C6: pa | D6: belem | E6: Brasil Midia Exterior | F6: Outdoor lonado | H6: X | I6: 1 | K6: X | M6: 15 | N6: 30 | O6: 25 | P6: Bisemanal | Q6: 25 | U6: 1 | V6: 2650 | W6: 0.1 | X6: =V6*(1-W6) -> 2385 | Y6: =X6*U6*O6 -> 59625
A7: data produto | B7: norte | C7: pa | D7: belem | E7: Ultra OOH | F7: Painel de Led | H7: X | I7: 2 | L7: X | M7: 6 | N7: 12 | O7: 1 | P7: Mensal | Q7: 1 | U7: 1 | V7: 5593 | W7: 0.25 | X7: =V7*(1-W7) -> 4194.75 | Y7: =X7*U7*O7 -> 4194.75
A8: data produto | B8: norte | C8: pa | D8: belem | E8: Ultra OOH | F8: Frontlight | H8: X | I8: 5 | K8: X | M8: 4 | N8: 8 | O8: 2 | P8: Mensal | Q8: 2 | U8: 1 | V8: =(10000+6680)/2 -> 8340 | W8: 0.3 | X8: =V8*(1-W8) -> 5838 | Y8: =X8*U8*O8 -> 11676
A9: data produto | B9: norte | C9: pa | D9: belem | E9: Ultra OOH | F9: Empena | H9: X | I9: 4 | K9: X | M9: 2 | N9: 5 | O9: 3 | P9: Mensal | Q9: 3 | U9: 1 | V9: =(13400+28000+16000)/3 -> 19133.333 | W9: 0.25 | X9: =V9*(1-W9) -> 14350 | Y9: =X9*U9*O9 -> 43050
A10: data produto | B10: norte | C10: pa | D10: belem | E10: Green Outdoor | F10: Painel de Led | H10: X | I10: 2 | L10: X | M10: 6 | N10: 12 | O10: 1 | P10: Mensal | Q10: 1 | U10: 1 | V10: 2362 | W10: 0.2 | X10: =V10*(1-W10) -> 1889.6 | Y10: =X10*U10*O10 -> 1889.6
A11: data produto | B11: norte | C11: pa | D11: belem | E11: Green Outdoor | F11: Outdoor lonado | H11: X | I11: 1 | K11: X | M11: 15 | N11: 30 | O11: 25 | P11: Mensal | S11: 25 | U11: 1 | V11: 2650 | W11: 0.2 | X11: =V11*(1-W11) -> 2120 | Y11: =X11*U11*O11 -> 53000
A12: data produto | B12: norte | C12: pa | D12: belem | E12: S2X Promoções | F12: Carro de Som | H12: X | I12: 6 | M12: 7 | N12: 30 | O12: 7 | P12: Diaria 8 horas | Q12: 7 | S12: 7 | U12: 2 | V12: =265*8 -> 2120 | W12: 0.4 | X12: =V12*(1-W12) -> 1272 | Y12: =X12*U12*O12 -> 17808
A13: data produto | B13: norte | C13: pa | D13: belem | E13: Prisma OOH | F13: Painel de Led | H13: X | I13: 2 | L13: X | M13: 6 | N13: 12 | O13: 2 | P13: Mensal | Q13: 2 | U13: 1 | V13: 7920 | W13: 0.25 | X13: =V13*(1-W13) -> 5940 | Y13: =X13*U13*O13 -> 11880
A14: data produto | B14: norte | C14: pa | D14: belem | E14: Puraka | F14: Painel de Led | H14: X | I14: 2 | L14: X | M14: 6 | N14: 12 | O14: 2 | P14: Mensal | Q14: 2 | U14: 1 | V14: 18500 | W14: 0.6 | X14: =V14*(1-W14) -> 7400 | Y14: =X14*U14*O14 -> 14800
A15: data produto | B15: norte | C15: pa | D15: belem | E15: Puraka | F15: Frontlight | H15: X | I15: 5 | K15: X | M15: 6 | N15: 12 | O15: 2 | P15: Mensal | Q15: 2 | U15: 1 | V15: 20500 | W15: 0.58 | X15: =V15*(1-W15) -> 8610 | Y15: =X15*U15*O15 -> 17220
A16: data produto | B16: norte | C16: pa | D16: belem | E16: Bureau de Mídia | F16: Painel de Led | H16: X | I16: 2 | L16: X | M16: 6 | N16: 12 | O16: 1 | P16: Mensal | Q16: 1 | U16: 1 | V16: 8125 | W16: 0.15 | X16: =V16*(1-W16) -> 6906.25 | Y16: =X16*U16*O16 -> 6906.25
A17: data produto | B17: norte | C17: pa | D17: belem | E17: Bureau de Mídia | F17: Envelopamento Barco | H17: X | I17: 3 | K17: X | M17: 1 | N17: 3 | O17: 1 | P17: Mensal | Q17: 1 | U17: 1 | V17: 73000 | W17: 0 | X17: =V17*(1-W17) -> 73000 | Y17: =X17*U17*O17 -> 73000
A19: data promo | B19: norte | C19: pa | D19: belem | E19: Eletromidia | F19: Painel de Led | H19: X | I19: 1 | L19: x | M19: 6 | N19: 12 | O19: 1 | P19: Semanal | Q19: 1 | S19: 1 | U19: 1 | V19: 5929 | W19: 0.6 | X19: =V19*(1-W19) -> 2371.6 | Y19: =X19*U19*O19 -> 2371.6
A20: data promo | B20: norte | C20: pa | D20: belem | E20: WeOOH | F20: Painel de Led | H20: X | I20: 1 | L20: x | M20: 6 | N20: 12 | O20: 2 | P20: Mensal | Q20: 2 | U20: 1 | V20: 27024.15 | W20: 0.75 | X20: =V20*(1-W20) -> 6756.0375 | Y20: =X20*U20*O20 -> 13512.075
A21: data promo | B21: norte | C21: pa | D21: belem | E21: Brasil Midia Exterior | F21: Painel de Led | H21: X | I21: 1 | L21: x | M21: 6 | N21: 12 | O21: 2 | P21: Mensal | Q21: 2 | U21: 1 | V21: 7000 | W21: 0.1 | X21: =V21*(1-W21) -> 6300 | Y21: =X21*U21*O21 -> 12600
A22: data promo | B22: norte | C22: pa | D22: belem | E22: Brasil Midia Exterior | F22: Frontlight | H22: X | I22: 5 | K22: x | M22: 4 | N22: 8 | O22: 1 | P22: Mensal | Q22: 1 | U22: 1 | V22: 7500 | W22: 0.1 | X22: =V22*(1-W22) -> 6750 | Y22: =X22*U22*O22 -> 6750
A23: data promo | B23: norte | C23: pa | D23: belem | E23: Brasil Midia Exterior | F23: Outdoor lonado | H23: X | I23: 2 | K23: x | M23: 15 | N23: 30 | O23: 30 | P23: Mensal | Q23: 30 | U23: 1 | V23: 2650 | W23: 0.1 | X23: =V23*(1-W23) -> 2385 | Y23: =X23*U23*O23 -> 71550
A24: data promo | B24: norte | C24: pa | D24: belem | E24: Ultra OOH | F24: Painel de Led | H24: X | I24: 1 | L24: x | M24: 6 | N24: 12 | O24: 1 | P24: Mensal | Q24: 1 | U24: 1 | V24: 5593 | W24: 0.25 | X24: =V24*(1-W24) -> 4194.75 | Y24: =X24*U24*O24 -> 4194.75
A25: data promo | B25: norte | C25: pa | D25: belem | E25: Ultra OOH | F25: Frontlight | H25: X | I25: 5 | K25: x | M25: 4 | N25: 8 | O25: 2 | P25: Mensal | Q25: 2 | U25: 1 | V25: =(10000+6680)/2 -> 8340 | W25: 0.3 | X25: =V25*(1-W25) -> 5838 | Y25: =X25*U25*O25 -> 11676
A26: data promo | B26: norte | C26: pa | D26: belem | E26: Green Outdoor | F26: Painel de Led | H26: X | I26: 1 | L26: x | M26: 6 | N26: 12 | O26: 1 | P26: Mensal | Q26: 1 | U26: 1 | V26: 2362 | W26: 0.2 | X26: =V26*(1-W26) -> 1889.6 | Y26: =X26*U26*O26 -> 1889.6
A27: data promo | B27: norte | C27: pa | D27: belem | E27: Green Outdoor | F27: Outdoor lonado | H27: X | I27: 2 | K27: x | M27: 15 | N27: 30 | O27: 30 | P27: Mensal | Q27: 30 | U27: 1 | V27: 2650 | W27: 0.2 | X27: =V27*(1-W27) -> 2120 | Y27: =X27*U27*O27 -> 63600
A28: data promo | B28: norte | C28: pa | D28: belem | E28: S2X Promoções | F28: Carro de Som | H28: X | I28: 3 | K28: x | M28: 7 | N28: 30 | O28: 7 | P28: Diaria 8 horas | Q28: 7 | U28: 1 | V28: =265*8 -> 2120 | W28: 0.4 | X28: =V28*(1-W28) -> 1272 | Y28: =X28*U28*O28 -> 8904
A29: data promo | B29: norte | C29: pa | D29: belem | E29: Prisma OOH | F29: Painel de Led | H29: X | I29: 1 | L29: x | M29: 6 | N29: 12 | O29: 2 | P29: Mensal | Q29: 2 | U29: 1 | V29: 7920 | W29: 0.25 | X29: =V29*(1-W29) -> 5940 | Y29: =X29*U29*O29 -> 11880
A30: data promo | B30: norte | C30: pa | D30: belem | E30: Puraka | F30: Painel de Led | H30: X | I30: 1 | L30: x | M30: 6 | N30: 12 | O30: 3 | P30: Mensal | Q30: 3 | U30: 1 | V30: 18500 | W30: 0.6 | X30: =V30*(1-W30) -> 7400 | Y30: =X30*U30*O30 -> 22200
A31: data promo | B31: norte | C31: pa | D31: belem | E31: Puraka | F31: Frontlight | H31: X | I31: 5 | K31: x | M31: 4 | N31: 8 | O31: 2 | P31: Mensal | Q31: 2 | U31: 1 | V31: 20500 | W31: 0.58 | X31: =V31*(1-W31) -> 8610 | Y31: =X31*U31*O31 -> 17220
A32: data promo | B32: norte | C32: pa | D32: belem | E32: Bureau de Mídia | F32: Painel de Led | H32: X | I32: 1 | L32: x | M32: 6 | N32: 12 | O32: 2 | P32: Mensal | Q32: 2 | U32: 1 | V32: 8125 | W32: 0.15 | X32: =V32*(1-W32) -> 6906.25 | Y32: =X32*U32*O32 -> 13812.5
A33: data promo | B33: norte | C33: pa | D33: belem | E33: Bureau de Mídia | F33: BikeDoor | H33: X | I33: 6 | K33: x | M33: 5 | N33: 10 | O33: 4 | P33: Diario | Q33: 4 | R33: 4 | S33: 4 | T33: 4 | U33: 4 | V33: 1944 | W33: 0.15 | X33: =V33*(1-W33) -> 1652.4 | Y33: =X33*U33*O33 -> 26438.4
A34: data promo | B34: norte | C34: pa | D34: belem | E34: Cartaxi | F34: Taxi - vidro traseiro | H34: X | I34: 4 | K34: x | M34: 10 | N34: 35 | O34: 20 | P34: Mensal | Q34: 20 | U34: 1 | V34: 1600 | W34: 0.5 | X34: =V34*(1-W34) -> 800 | Y34: =X34*U34*O34 -> 16000
A36: ouro produto | B36: norte | C36: pa | D36: belem | E36: WeOOH | F36: Painel de Led | H36: X | I36: 2 | L36: x | M36: 4 | N36: 8 | O36: 1 | P36: Mensal | Q36: 1 | U36: 1 | V36: 27024.15 | W36: 0.75 | X36: =V36*(1-W36) -> 6756.0375 | Y36: =X36*U36*O36 -> 6756.0375
A37: ouro produto | B37: norte | C37: pa | D37: belem | E37: Brasil Midia Exterior | F37: Painel de Led | H37: X | I37: 2 | L37: x | M37: 4 | N37: 8 | O37: 1 | P37: Mensal | Q37: 1 | U37: 1 | V37: 7000 | W37: 0.1 | X37: =V37*(1-W37) -> 6300 | Y37: =X37*U37*O37 -> 6300
A38: ouro produto | B38: norte | C38: pa | D38: belem | E38: Brasil Midia Exterior | F38: Frontlight | H38: X | I38: 5 | K38: x | M38: 3 | N38: 6 | O38: 1 | P38: Mensal | Q38: 1 | U38: 1 | V38: 7500 | W38: 0.1 | X38: =V38*(1-W38) -> 6750 | Y38: =X38*U38*O38 -> 6750
A39: ouro produto | B39: norte | C39: pa | D39: belem | E39: Brasil Midia Exterior | F39: Outdoor lonado | H39: X | I39: 1 | K39: x | M39: 10 | N39: 20 | O39: 18 | P39: Mensal | Q39: 18 | U39: 1 | V39: 2650 | W39: 0.1 | X39: =V39*(1-W39) -> 2385 | Y39: =X39*U39*O39 -> 42930
A40: ouro produto | B40: norte | C40: pa | D40: belem | E40: Ultra OOH | F40: Painel de Led | H40: X | I40: 2 | L40: x | M40: 4 | N40: 8 | O40: 1 | P40: Mensal | Q40: 1 | U40: 1 | V40: 5593 | W40: 0.25 | X40: =V40*(1-W40) -> 4194.75 | Y40: =X40*U40*O40 -> 4194.75
A41: ouro produto | B41: norte | C41: pa | D41: belem | E41: Ultra OOH | F41: Frontlight | H41: X | I41: 5 | K41: x | M41: 3 | N41: 6 | O41: 2 | P41: Mensal | Q41: 2 | U41: 1 | V41: =(10000+6680)/2 -> 8340 | W41: 0.3 | X41: =V41*(1-W41) -> 5838 | Y41: =X41*U41*O41 -> 11676
A42: ouro produto | B42: norte | C42: pa | D42: belem | E42: Ultra OOH | F42: Empena | H42: X | I42: 4 | K42: x | M42: 1 | N42: 3 | O42: 3 | P42: Mensal | Q42: 3 | U42: 1 | V42: =(13400+28000+16000)/3 -> 19133.333 | W42: 0.25 | X42: =V42*(1-W42) -> 14350 | Y42: =X42*U42*O42 -> 43050
...

Sheet BOA VISTA
A1: =[14]BASE!A2 -> ESTUDO BOA VISTA
A2: IBGE 2024/ CENSO 2022
A7: INVESTIMENTO BOA VISTA CAPITAL OOH 2024 | B7: 249713.29
A8: INVESTIMENTO RORAIMA OOH 2024 | B8: 249713.29
A10: R$ BRUTO BOA VISTA CAPITAL - 2025 OOH | B10: 657396.25
A11: BUDGET BRUTO RORAIMA 2025 OOH (100%) | B11: 657396.25
A14: Exclusão de Bronze
A15: CICLOS/MEDALHAS | C15: % BUDGET/CICLO | D15: R$ MEDALHA | E15: R$ UNIT. MEDALHAS
A16: Data | B16: 3 - 2 produto/1 promo | C16: 0.44 | D16: 289254.35 | E16: 96418.117
A17: Ouro | B17: 5 - 4 produto/ 1 promo | C17: 0.48 | D17: 315550.2 | E17: 63110.04
A18: Prata | B18: 2 | C18: 0.08 | D18: 52591.7 | E18: 26295.85
B19: 10 ciclos | C19: 1 | D19: 657396.25
A21: População Capital | B21: 413486
A22: População Target - AS ABC 18/49 (logan) | B22: 223605
E23: Cobertura total - Data Produto | F23: 39% | H23: Cobertura total - Data Promo | J23: 0.49
E24: Frequencia | F24: 26 | H24: Frequencia | J24: 35
E25: TRP | F25: 326 | H25: TRP | J25: 590
E26: OTS | F26: 1.345.892 | H26: OTS | J26: 2145987
A28: Programação - Ciclo Data Produto
A30: 1 CICLO | T30: TOTAL ANO / CICLO
A31: Praça | B31: Exibidores | C31: Pen/Aff | D31: Canais | E31: Formato | F31: Range de volume ideal | G31: Qtdade | H31: Periodicidade | I31: Mês Base | M31: TT | N31: R$ Unit Bruto | O31: Desconto | P31: R$ Unit Bruto | Q31: R$ TT Bruto | R31: C.P.M. Formato | S31: % | T31: R$ Total | U31: AMBIENTES | Z31: FORMATO | AB31: EMPRESAS
I32: S1 | J32: S2 | K32: S3 | L32: S4 | M32: Flight | N32: Tabela | O32: (%) | P32: Negociado | Q32: Negociado | T32: ano
A33: DATAS MÃES/NATAL | U33: GDES | V33: MUB | W33: TRANSP | X33: AERO | Y33: OPORT | Z33: ESTÁTICO | AA33: DIGITAL | AB33: M2 | AC33: TELAS PROMO | AD33: KALLAS
A35: Boa Vista - RR | B35: M2 comunicações | C35: 50/156 | D35: Frontlight | E35: Estático | F35: 3/5 | G35: 3 | H35: Mensal | I35: 3 | M35: 1 | N35: 4480 | O35: 0.2 | P35: =N35*(1-O35) -> 3584 | Q35: =P35*M35*G35 -> 10752 | R35: =(Q35+Q36+#REF!+#REF!)/E11*1000 -> #REF! | S35: =Q35/$Q$43 -> 0.25844911 | T35: =Q35*2 -> 21504 | U35: =T35 -> 21504 | AA35: =T35 -> 21504 | AB35: =T35 -> 21504
A36: Boa Vista - RR | B36: Telas Promo | C36: 50/156 | D36: Painel de Led | E36: Digital | F36: 2/4 | G36: 2 | H36: Mensal | I36: 2 | M36: 1 | N36: 5000 | O36: 0.25 | P36: =N36*(1-O36) -> 3750 | Q36: =P36*M36*G36 -> 7500 | R36: =(Q36+Q37+#REF!+#REF!)/E12*1000 -> #REF! | S36: =Q36/$Q$43 -> 0.18027979 | T36: =Q36*2 -> 15000 | U36: =T36 -> 15000 | Z36: =T36 -> 15000 | AC36: =T36 -> 15000
A37: Boa Vista - RR | B37: Telas Promo | C37: 50/156 | D37: Circuito interno Led | E37: Digital | F37: 1/2 | G37: 2 | H37: Mensal | I37: 2 | M37: 1 | N37: 5000 | O37: 0.25 | P37: =N37*(1-O37) -> 3750 | Q37: =P37*M37*G37 -> 7500 | S37: =Q37/$Q$43 -> 0.18027979 | T37: =Q37*2 -> 15000 | V37: =T37 -> 15000 | Z37: =T37 -> 15000 | AC37: =T37 -> 15000
A38: Boa Vista - RR | B38: Telas Promo | C38: 50/156 | D38: Frontlight | E38: Estático | F38: 3/5 | G38: 2 | H38: Mensal | I38: 2 | M38: 1 | N38: 5500 | O38: 0.25 | P38: =N38*(1-O38) -> 4125 | Q38: =P38*M38*G38 -> 8250 | S38: =Q38/$Q$43 -> 0.19830777 | T38: =Q38*2 -> 16500 | U38: =T38 -> 16500 | AA38: =T38 -> 16500 | AC38: =U38 -> 16500
AD39: =T39 -> 0
A40: Boa Vista - RR | B40: Aeroporto | T40: =Q40*2 -> 0 | X40: =T40 -> 0
A41: Boa Vista - RR | B41: Oportunidades | D41: Marítimos / Ativação | Q41: 7600 | S41: =Q41/Q43 -> 0.18268352 | T41: =Q41*2 -> 15200 | Y41: =T41 -> 15200
A43: Total faces compra | I43: =I38+I37+I36+I35 -> 9 | M43: =SUM(I43:L43) -> 9 | Q43: =SUM(Q35:Q42) -> 41602 | S43: =SUM(S35:S41) -> 1 | T43: =SUM(T35:T42) -> 83204 | U43: =SUM(U35:U41) -> 53004 | V43: =SUM(V35:V41) -> 15000 | W43: =SUM(W35:W41) -> 0 | X43: =SUM(X35:X41) -> 0 | Y43: =SUM(Y35:Y41) -> 15200 | Z43: =SUM(Z35:Z41) -> 30000 | AA43: =SUM(AA35:AA41) -> 38004 | AB43: =SUM(AB35:AB42) -> 21504 | AC43: =SUM(AC34:AC40) -> 46500 | AD43: =SUM(AD34:AD40) -> 0
A44: Total faces simulação | I44: =I38+I37+I36+I35 -> 9 | J44: =I38+I37+I36+I35 -> 9 | K44: =I38+I37+I36+I35 -> 9 | L44: =I38+I37+I36+I35 -> 9 | M44: =SUM(I44:L44) -> 36 | U44: =U43/T43 -> 0.63703668 | V44: =V43/T43 -> 0.18027979 | W44: =W43/T43 -> 0 | X44: =X43/T43 -> 0 | Y44: =Y43/T43 -> 0.18268352 | Z44: =Z43/T43 -> 0.36055959 | AA44: =AA43/T43 -> 0.45675689
A45: Grandes Formatos | Q45: =U43/2 -> 26502 | S45: =Q45/Q50 -> 0.63703668 | Y45: =SUM(U35:Y42) -> 83204 | Z45: =I36+I37 -> 4 | AA45: =I35+I38 -> 5
A46: MUB | Q46: =V43/2 -> 7500 | S46: =Q46/Q50 -> 0.18027979 | T46: =Q43/M43 -> 4622.4444 | U46: CPFACE | Z46: =Z45/M43 -> 0.44444444 | AA46: =AA45/M43 -> 0.55555556
A47: Transportes | Q47: =W43/2 -> 0 | S47: =Q47/Q50 -> 0 | Z47: SHARE FACES
A48: Oportunidades | Q48: =Y43/2 -> 7600 | S48: =Q48/Q50 -> 0.18268352
A49: Aeroporto | Q49: =X43/2 -> 0 | S49: =Q49/Q50 -> 0
Q50: =SUM(Q45:Q49) -> 41602 | S50: =SUM(S45:S49) -> 1
A52: Programação - Ciclo Data Promo
A54: 1 CICLO | T54: TOTAL ANO / CICLO
...

Sheet BOA VISTA PLAN
A1: taxonomia | B1: regional_boticario | C1: uf | D1: praca | E1: exibidores | F1: formato | G1: circuito | H1: avulso | I1: ranking | J1: pesos | K1: estatico | L1: digital | M1: range_minimo | N1: range_maximo | O1: quantidade | P1: periodicidade | Q1: s1 | R1: s2 | S1: s3 | T1: s4 | U1: flight | V1: unitario_bruto_tabela | W1: desconto | X1: unitario_bruto_negociado | Y1: total_bruto_negociado
A2: data produto | B2: norte | C2: rr | D2: boa vista | E2: M2 comunicações | F2: Frontlight | H2: X | I2: 1 | K2: x | M2: 3 | N2: 5 | O2: 3 | P2: Mensal | Q2: 3 | S2: 1 | U2: 1 | V2: 4480 | W2: 0.2 | X2: =V2*(1-W2) -> 3584 | Y2: =X2*U2*O2 -> 10752
A3: data produto | B3: norte | C3: rr | D3: boa vista | E3: Telas Promo | F3: Painel de Led | H3: X | I3: 2 | L3: X | M3: 2 | N3: 4 | O3: 2 | P3: Mensal | Q3: 2 | U3: 1 | V3: 5000 | W3: 0.25 | X3: =V3*(1-W3) -> 3750 | Y3: =X3*U3*O3 -> 7500
A4: data produto | B4: norte | C4: rr | D4: boa vista | E4: Telas Promo | F4: Circuito interno Led | G4: X | I4: 3 | L4: X | M4: 1 | N4: 2 | O4: 2 | P4: Mensal | Q4: 2 | U4: 1 | V4: 5000 | W4: 0.25 | X4: =V4*(1-W4) -> 3750 | Y4: =X4*U4*O4 -> 7500
A5: data produto | B5: norte | C5: rr | D5: boa vista | E5: Telas Promo | F5: Frontlight | H5: X | I5: 1 | K5: X | M5: 3 | N5: 5 | O5: 2 | P5: Mensal | Q5: 2 | U5: 1 | V5: 5500 | W5: 0.25 | X5: =V5*(1-W5) -> 4125 | Y5: =X5*U5*O5 -> 8250
A7: data promo | B7: norte | C7: rr | D7: boa vista | E7: M2 comunicações | F7: Frontlight | H7: X | I7: 3 | K7: x | M7: 2 | N7: 3 | O7: 2 | P7: Mensal | Q7: 2 | U7: 1 | V7: 4480 | W7: 0.2 | X7: =V7*(1-W7) -> 3584 | Y7: =X7*U7*O7 -> 7168
A8: data promo | B8: norte | C8: rr | D8: boa vista | E8: Telas Promo | F8: Painel de Led | H8: X | I8: 1 | L8: x | M8: 2 | N8: 4 | O8: 2 | P8: Mensal | Q8: 2 | U8: 1 | V8: 5000 | W8: 0.25 | X8: =V8*(1-W8) -> 3750 | Y8: =X8*U8*O8 -> 7500
A9: data promo | B9: norte | C9: rr | D9: boa vista | E9: Telas Promo | F9: Circuito interno Led | G9: X | I9: 4 | L9: x | M9: 1 | N9: 2 | O9: 2 | P9: Mensal | Q9: 2 | U9: 1 | V9: 5000 | W9: 0.25 | X9: =V9*(1-W9) -> 3750 | Y9: =X9*U9*O9 -> 7500
A10: data promo | B10: norte | C10: rr | D10: boa vista | E10: Telas Promo | F10: Frontlight | H10: X | I10: 3 | K10: x | M10: 1 | N10: 2 | O10: 1 | P10: Mensal | Q10: 1 | U10: 1 | V10: 5500 | W10: 0.25 | X10: =V10*(1-W10) -> 4125 | Y10: =X10*U10*O10 -> 4125
A11: data promo | B11: norte | C11: rr | D11: boa vista | E11: Cartaxi | F11: Vidro traseiro + interno | H11: X | I11: 5 | K11: x | M11: 3 | N11: 8 | O11: 8 | P11: Mensal | Q11: 8 | U11: 1 | V11: 1600 | W11: 0.7 | X11: =V11*(1-W11) -> 480 | Y11: =X11*U11*O11 -> 3840
A12: data promo | B12: norte | C12: rr | D12: boa vista | E12: Telas Promo | F12: Busdoor | H12: X | I12: 2 | K12: x | M12: 2 | N12: 5 | O12: 4 | P12: Mensal | Q12: 4 | U12: 1 | V12: 2000 | W12: 0.45 | X12: =V12*(1-W12) -> 1100 | Y12: =X12*U12*O12 -> 4400
A14: ouro produto | B14: norte | C14: rr | D14: boa vista | E14: M2 comunicações | F14: Frontlight | H14: X | I14: 1 | K14: x | M14: 2 | N14: 3 | O14: 2 | P14: Mensal | Q14: 2 | U14: 1 | V14: 4480 | W14: 0.2 | X14: =V14*(1-W14) -> 3584 | Y14: =X14*U14*O14 -> 7168
A15: ouro produto | B15: norte | C15: rr | D15: boa vista | E15: Telas Promo | F15: Painel de Led | H15: X | I15: 2 | L15: x | M15: 2 | N15: 4 | O15: 2 | P15: Mensal | Q15: 2 | U15: 1 | V15: 5000 | W15: 0.25 | X15: =V15*(1-W15) -> 3750 | Y15: =X15*U15*O15 -> 7500
A16: ouro produto | B16: norte | C16: rr | D16: boa vista | E16: Telas Promo | F16: Circuito interno Led | G16: X | I16: 3 | L16: x | M16: 1 | N16: 2 | O16: 2 | P16: Mensal | Q16: 2 | U16: 1 | V16: 5000 | W16: 0.25 | X16: =V16*(1-W16) -> 3750 | Y16: =X16*U16*O16 -> 7500
A17: ouro produto | B17: norte | C17: rr | D17: boa vista | E17: Telas Promo | F17: Frontlight | H17: X | I17: 1 | K17: x | M17: 1 | N17: 2 | O17: 1 | P17: Mensal | Q17: 1 | U17: 1 | V17: 5500 | W17: 0.25 | X17: =V17*(1-W17) -> 4125 | Y17: =X17*U17*O17 -> 4125
A19: ouro promo | B19: norte | C19: rr | D19: boa vista | E19: M2 comunicações | F19: Frontlight | H19: X | I19: 3 | K19: x | M19: 2 | N19: 3 | O19: 1 | P19: Mensal | Q19: 1 | U19: 1 | V19: 4480 | W19: 0.2 | X19: =V19*(1-W19) -> 3584 | Y19: =X19*U19*O19 -> 3584
A20: ouro promo | B20: norte | C20: rr | D20: boa vista | E20: Telas Promo | F20: Painel de Led | H20: X | I20: 1 | L20: x | M20: 2 | N20: 4 | O20: 2 | P20: Mensal | Q20: 2 | U20: 1 | V20: 5000 | W20: 0.25 | X20: =V20*(1-W20) -> 3750 | Y20: =X20*U20*O20 -> 7500
A21: ouro promo | B21: norte | C21: rr | D21: boa vista | E21: Telas Promo | F21: Circuito interno Led | G21: X | I21: 4 | L21: x | M21: 1 | N21: 2 | O21: 2 | P21: Mensal | Q21: 2 | U21: 1 | V21: 5000 | W21: 0.25 | X21: =V21*(1-W21) -> 3750 | Y21: =X21*U21*O21 -> 7500
A22: ouro promo | B22: norte | C22: rr | D22: boa vista | E22: Telas Promo | F22: Frontlight | H22: X | I22: 3 | K22: x | M22: 1 | N22: 2 | O22: 1 | P22: Mensal | Q22: 1 | U22: 1 | V22: 5500 | W22: 0.25 | X22: =V22*(1-W22) -> 4125 | Y22: =X22*U22*O22 -> 4125
A23: ouro promo | B23: norte | C23: rr | D23: boa vista | E23: Cartaxi | F23: Vidro traseiro + interno | H23: X | I23: 5 | K23: x | M23: 3 | N23: 8 | O23: 6 | P23: Mensal | Q23: 6 | U23: 1 | V23: 1600 | W23: 0.7 | X23: =V23*(1-W23) -> 480 | Y23: =X23*U23*O23 -> 2880
A24: ouro promo | B24: norte | C24: rr | D24: boa vista | E24: Telas Promo | F24: Busdoor | H24: X | I24: 2 | K24: x | M24: 2 | N24: 5 | O24: 3 | P24: Mensal | Q24: 3 | U24: 1 | V24: 2000 | W24: 0.45 | X24: =V24*(1-W24) -> 1100 | Y24: =X24*U24*O24 -> 3300
A26: prata | B26: norte | C26: rr | D26: boa vista | E26: M2 comunicações | F26: Frontlight | H26: X | I26: 3 | K26: x | M26: 2 | N26: 3 | O26: 1 | P26: Mensal | Q26: 1 | U26: 1 | V26: 4480 | W26: 0.2 | X26: =V26*(1-W26) -> 3584 | Y26: =X26*U26*O26 -> 3584
A27: prata | B27: norte | C27: rr | D27: boa vista | E27: Telas Promo | F27: Painel de Led | H27: X | I27: 1 | L27: x | M27: 2 | N27: 4 | O27: 1 | P27: Mensal | Q27: 1 | U27: 1 | V27: 5000 | W27: 0.25 | X27: =V27*(1-W27) -> 3750 | Y27: =X27*U27*O27 -> 3750
A28: prata | B28: norte | C28: rr | D28: boa vista | E28: Telas Promo | F28: Circuito interno Led | G28: X | I28: 4 | L28: x | M28: 1 | N28: 2 | O28: 1 | P28: Mensal | Q28: 1 | U28: 1 | V28: 5000 | W28: 0.25 | X28: =V28*(1-W28) -> 3750 | Y28: =X28*U28*O28 -> 3750
A29: prata | B29: norte | C29: rr | D29: boa vista | E29: Telas Promo | F29: Frontlight | H29: X | I29: 3 | K29: x | M29: 1 | N29: 2 | O29: 1 | P29: Mensal | Q29: 1 | U29: 1 | V29: 5500 | W29: 0.25 | X29: =V29*(1-W29) -> 4125 | Y29: =X29*U29*O29 -> 4125
A30: prata | B30: norte | C30: rr | D30: boa vista | E30: Cartaxi | F30: Vidro traseiro + interno | H30: X | I30: 5 | K30: x | M30: 3 | N30: 8 | O30: 2 | P30: Mensal | Q30: 2 | U30: 1 | V30: 1600 | W30: 0.7 | X30: =V30*(1-W30) -> 480 | Y30: =X30*U30*O30 -> 960
A31: prata | B31: norte | C31: rr | D31: boa vista | E31: Telas Promo | F31: Busdoor | H31: X | I31: 2 | K31: x | M31: 2 | N31: 5 | O31: 1 | P31: Mensal | Q31: 1 | U31: 1 | V31: 2000 | W31: 0.45 | X31: =V31*(1-W31) -> 1100 | Y31: =X31*U31*O31 -> 1100
E36: cpf mínimo | F36: cpf plano | G36: cpf máximo
A37: DATA PRODUTO | E37: =F37*(1-10%) -> 4160.2 | F37: ='BOA VISTA'!T46 -> 4622.4444 | G37: =F37*(1+15%) -> 5315.8111
A38: DATA PROMO | E38: =F38*(1-25%) -> 1663.1447 | F38: ='BOA VISTA'!T73 -> 2217.5263 | G38: =F38*(1+5%) -> 2328.4026
A39: OURO PRODUTO | E39: =F39*(1-15%) -> 3860.5786 | F39: ='BOA VISTA'!T102 -> 4541.8571 | G39: =F39*(1+15%) -> 5223.1357
A40: OURO PROMO | E40: =F40*(1-25%) -> 1719.45 | F40: ='BOA VISTA'!T133 -> 2292.6 | G40: =F40*(1+5%) -> 2407.23
A41: PRATA | E41: =F41*(1-25%) -> 2118.1071 | F41: ='BOA VISTA'!T167 -> 2824.1429 | G41: =F41*(1+5%) -> 2965.35
E43: ranking semanas - distribuição investimento
A44: DATA PRODUTO | E44: 1
A45: DATA PROMO | E45: 1
A46: OURO PRODUTO | E46: 1
A47: OURO PROMO | E47: 1
A48: PRATA | E48: 1
E52: ranking semanas - distribuição audiência
...

Sheet MACAPA
A1: =[15]BASE!A2 -> ESTUDO MACAPA
A2: IBGE 2024/ CENSO 2022
A6: INVESTIMENTO MACAPA CAPITAL OOH 2024 | B6: 393739.8
A7: INVESTIMENTO AMAPA OOH 2024 | B7: 393739.8
A9: R$ BRUTO MACAPA CAPITAL - 2025 OOH | B9: 1077573.8
A10: BUDGET BRUTO AMAPA 2025 OOH (100%) | B10: 1077573.8
A13: Exclusão de Bronze
A14: CICLOS/MEDALHAS | C14: % BUDGET/CICLO | D14: R$ MEDALHA | E14: R$ UNIT. MEDALHAS
A15: Datas (c6/c16/c17) | B15: 3 - 2 produto/1 promo | C15: 0.44 | D15: 474132.45 | E15: 158044.15
A16: Ouro (c1/c4/c11/c13) | B16: 5 - 4 produto/ 1 promo | C16: 0.48 | D16: 517235.4 | E16: 103447.08
A17: Prata (c3/c8/c10/c14) | B17: 2 | C17: 0.08 | D17: 86205.9 | E17: 43102.95
B18: 10 ciclos | C18: 1 | D18: 1077573.8
A21: População Capital | B21: 442933
A22: População Target - AS ABC 18/49 (logan) | B22: 249133 | E22: Cobertura total - Data Produto | F22: 32% | H22: Cobertura total - Data Promo | J22: 0.34
E23: Frequencia | F23: 23 | H23: Frequencia | J23: 25
E24: TRP | F24: 697 | H24: TRP | J24: 735
E25: OTS | F25: 1.735.289 | H25: OTS | J25: 1831500
A27: Programação - Ciclo Data Produto
A29: 1 CICLO | T29: TOTAL ANO / CICLO
A30: Praça | B30: Exibidores | C30: Pen/Aff | D30: Canais | E30: Formato | F30: Range de volume ideal | G30: Qtdade | H30: Periodicidade | I30: Mês Base | M30: TT | N30: R$ Unit Bruto | O30: Desconto | P30: R$ Unit Bruto | Q30: R$ TT Bruto | R30: C.P.M. Formato | S30: % | T30: R$ Total | U30: AMBIENTES | Z30: FORMATO | AB30: EMPRESAS
I31: S1 | J31: S2 | K31: S3 | L31: S4 | M31: Flight | N31: Tabela | O31: (%) | P31: Negociado | Q31: Negociado | T31: ano
A32: DATAS MÃES/NATAL | U32: GDES | V32: MUB | W32: TRANSP | X32: AERO | Y32: OPORT | Z32: ESTÁTICO | AA32: DIGITAL | AB32: BUREAU | AC32: ATOS
A34: Macapá - AP | B34: Bureau de mídia | C34: 50/156 | D34: Frontlight | E34: Estático | F34: 2/3 | G34: 2 | H34: Mensal | I34: 2 | M34: 1 | N34: 5200 | O34: 0.34 | P34: =N34*(1-O34) -> 3432 | Q34: =P34*M34*G34 -> 6864 | R34: =(Q34+Q35+Q39+#REF!)/E7*1000 -> #REF! | S34: =Q34/$Q$43 -> 0.11259843 | T34: =Q34*2 -> 13728 | U34: =T34 -> 13728 | AA34: =T34 -> 13728 | AB34: =T34 -> 13728
A35: Macapá - AP | B35: Bureau de mídia | C35: 50/156 | D35: Painel de Led | E35: Digital | F35: 2/4 | G35: 2 | H35: Mensal | I35: 2 | M35: 1 | N35: 7800 | O35: 0.34 | P35: =N35*(1-O35) -> 5148 | Q35: =P35*M35*G35 -> 10296 | R35: =(Q35+Q38+#REF!+#REF!)/E8*1000 -> #REF! | S35: =Q35/$Q$43 -> 0.16889764 | T35: =Q35*2 -> 20592 | U35: =T35 -> 20592 | AA35: =T35 -> 20592 | AB35: =T35 -> 20592
A36: Macapá - AP | B36: Atos | C36: 50/156 | D36: Frontlight | E36: Estático | F36: 2/4 | G36: 1 | H36: Mensal | I36: 1 | M36: 1 | N36: 3500 | O36: 0.2 | P36: =N36*(1-O36) -> 2800 | Q36: =P36*M36*G36 -> 2800 | S36: =Q36/$Q$43 -> 0.045931759 | T36: =Q36*2 -> 5600 | U36: =T36 -> 5600 | AA36: =T36 -> 5600 | AC36: =T36 -> 5600
A37: Macapá - AP | B37: Atos | C37: 50/156 | D37: Outdoor lonado | E37: Estático | F37: 8/13 | G37: 15 | H37: Mensal | I37: 15 | M37: 1 | N37: 1500 | O37: 0.2 | P37: =N37*(1-O37) -> 1200 | Q37: =P37*M37*G37 -> 18000 | R37: =(Q37+#REF!)/E6*1000 -> #REF! | S37: =Q37/$Q$43 -> 0.29527559 | T37: =Q37*2 -> 36000 | U37: =T37 -> 36000 | Z37: =T37 -> 36000 | AC37: =T37 -> 36000
A38: Macapá - AP | B38: Atos | C38: 50/156 | D38: Outdoor lonado | E38: Estático | F38: 10/25 | G38: 15 | H38: Mensal | K38: 15 | M38: 1 | N38: 1500 | O38: 0.2 | P38: =N38*(1-O38) -> 1200 | Q38: =P38*M38*G38 -> 18000 | R38: =(Q38+#REF!)/E8*1000 -> #REF! | S38: =Q38/$Q$43 -> 0.29527559 | T38: =Q38*2 -> 36000 | U38: =T38 -> 36000 | Z38: =T38 -> 36000 | AC38: =T38 -> 36000
A40: Macapá- AP | B40: Aeroporto | X40: =T40 -> 0
A41: Macapá-AP | B41: Oportunidades | D41: Marítimos / Ativação | Q41: 5000 | S41: =Q41/Q43 -> 0.082020997 | T41: =Q41*2 -> 10000 | Y41: =T41 -> 10000
I42: =I43/M43 -> 0.57142857 | K42: =K43/M43 -> 0.42857143
A43: Total faces compra | I43: =I37+I36+I35+I34 -> 20 | K43: =K38 -> 15 | M43: =SUM(I43:L43) -> 35 | Q43: =SUM(Q34:Q42) -> 60960 | S43: =SUM(S34:S41) -> 1 | T43: =SUM(T34:T42) -> 121920 | U43: =SUM(U34:U41) -> 111920 | V43: =SUM(V34:V41) -> 0 | W43: =SUM(W34:W41) -> 0 | X43: =SUM(X34:X41) -> 0 | Y43: =SUM(Y34:Y41) -> 10000 | Z43: =SUM(Z34:Z41) -> 72000 | AA43: =SUM(AA34:AA41) -> 39920 | AB43: =SUM(AB34:AB42) -> 34320 | AC43: =SUM(AC34:AC42) -> 77600
A44: Total faces simulação | I44: =I37+I36+I35+I34 -> 20 | J44: =I37+I36+I35+I34 -> 20 | K44: =K38+I36+I35+I34 -> 20 | L44: =K38+I36+I35+I34 -> 20 | M44: =SUM(I44:L44) -> 80 | U44: =U43/T43 -> 0.917979 | V44: =V43/T43 -> 0 | W44: =W43/T43 -> 0 | X44: =X43/T43 -> 0 | Y44: =Y43/T43 -> 0.082020997 | Z44: =Z43/T43 -> 0.59055118 | AA44: =AA43/T43 -> 0.32742782
A45: Grandes Formatos | Q45: =U43/2 -> 55960 | S45: =Q45/Q50 -> 0.917979 | Z45: =I34+I36+I37+K38 -> 33 | AA45: =I35 -> 2
A46: MUB | Q46: =V43/2 -> 0 | S46: =Q46/Q50 -> 0 | T46: =Q43/M43 -> 1741.7143 | U46: CPFACE | Z46: =Z45/M43 -> 0.94285714 | AA46: =AA45/M43 -> 0.057142857
A47: Transportes | Q47: =W43/2 -> 0 | S47: =Q47/Q50 -> 0 | Z47: SHARE FACES
A48: Oportunidades | Q48: =Y43/2 -> 5000 | S48: =Q48/Q50 -> 0.082020997
A49: Aeroporto | Q49: =X43/2 -> 0 | S49: =Q49/Q50 -> 0
Q50: =SUM(Q45:Q49) -> 60960 | S50: =SUM(S45:S49) -> 1
A52: Programação - Ciclo Data Promo
A54: 1 CICLO | T54: TOTAL ANO / CICLO
...

Sheet MACAPA PLAN
A1: taxonomia | B1: regional_boticario | C1: uf | D1: praca | E1: exibidores | F1: formato | G1: circuito | H1: avulso | I1: ranking | J1: pesos | K1: estatico | L1: digital | M1: range_minimo | N1: range_maximo | O1: quantidade | P1: periodicidade | Q1: s1 | R1: s2 | S1: s3 | T1: s4 | U1: flight | V1: unitario_bruto_tabela | W1: desconto | X1: unitario_bruto_negociado | Y1: total_bruto_negociado
A2: data produto | B2: norte | C2: ap | D2: macapa | E2: Bureau de mídia | F2: Frontlight | H2: x | I2: 3 | K2: x | M2: 2 | N2: 3 | O2: 2 | P2: Mensal | Q2: 2 | S2: 1 | U2: 1 | V2: 5200 | W2: 0.34 | X2: =V2*(1-W2) -> 3432 | Y2: =X2*U2*O2 -> 6864
A3: data produto | B3: norte | C3: ap | D3: macapa | E3: Bureau de mídia | F3: Painel de Led | H3: x | I3: 2 | L3: X | M3: 2 | N3: 4 | O3: 2 | P3: Mensal | Q3: 2 | U3: 1 | V3: 7800 | W3: 0.34 | X3: =V3*(1-W3) -> 5148 | Y3: =X3*U3*O3 -> 10296
A4: data produto | B4: norte | C4: ap | D4: macapa | E4: Atos | F4: Frontlight | H4: x | I4: 3 | K4: x | M4: 2 | N4: 4 | O4: 1 | P4: Mensal | Q4: 1 | U4: 1 | V4: 3500 | W4: 0.2 | X4: =V4*(1-W4) -> 2800 | Y4: =X4*U4*O4 -> 2800
A5: data produto | B5: norte | C5: ap | D5: macapa | E5: Atos | F5: Outdoor lonado | H5: x | I5: 1 | K5: X | M5: 10 | N5: 20 | O5: 15 | P5: Mensal | Q5: 15 | U5: 1 | V5: 1500 | W5: 0.2 | X5: =V5*(1-W5) -> 1200 | Y5: =X5*U5*O5 -> 18000
A6: data produto | B6: norte | C6: ap | D6: macapa | E6: Atos | F6: Outdoor lonado | H6: x | I6: 1 | K6: x | M6: 10 | N6: 20 | O6: 15 | P6: Mensal | S6: 15 | U6: 1 | V6: 1500 | W6: 0.2 | X6: =V6*(1-W6) -> 1200 | Y6: =X6*U6*O6 -> 18000
A8: data promo | B8: norte | C8: ap | D8: macapa | E8: Bureau de mídia | F8: Frontlight | H8: x | I8: 4 | K8: x | M8: 2 | N8: 3 | O8: 1 | P8: Mensal | Q8: 1 | U8: 1 | V8: 5200 | W8: 0.34 | X8: =V8*(1-W8) -> 3432 | Y8: =X8*U8*O8 -> 3432
A9: data promo | B9: norte | C9: ap | D9: macapa | E9: Bureau de mídia | F9: Painel de Led | H9: x | I9: 1 | L9: x | M9: 2 | N9: 4 | O9: 1 | P9: Mensal | Q9: 1 | U9: 1 | V9: 7800 | W9: 0.34 | X9: =V9*(1-W9) -> 5148 | Y9: =X9*U9*O9 -> 5148
A10: data promo | B10: norte | C10: ap | D10: macapa | E10: Bureau de mídia | F10: Busdoor | H10: x | I10: 2 | K10: x | M10: 5 | N10: 10 | O10: 3 | P10: Mensal | Q10: 3 | U10: 1 | V10: 1550 | W10: 0.2 | X10: =V10*(1-W10) -> 1240 | Y10: =X10*U10*O10 -> 3720
A11: data promo | B11: norte | C11: ap | D11: macapa | E11: Bureau de mídia | F11: Bikedoor | H11: x | I11: 5 | K11: x | M11: 2 | N11: 5 | O11: 4 | P11: Diaria | Q11: 4 | S11: 4 | U11: 2 | V11: 2450 | W11: 0.2 | X11: =V11*(1-W11) -> 1960 | Y11: =X11*U11*O11 -> 15680
A12: data promo | B12: norte | C12: ap | D12: macapa | E12: Atos | F12: Frontlight | H12: x | I12: 4 | K12: x | M12: 2 | N12: 4 | O12: 1 | P12: Mensal | Q12: 1 | U12: 1 | V12: 3500 | W12: 0.2 | X12: =V12*(1-W12) -> 2800 | Y12: =X12*U12*O12 -> 2800
A13: data promo | B13: norte | C13: ap | D13: macapa | E13: Atos | F13: Outdoor lonado | H13: x | I13: 3 | K13: x | M13: 10 | N13: 20 | O13: 13 | P13: Mensal | Q13: 13 | U13: 1 | V13: 1500 | W13: 0.2 | X13: =V13*(1-W13) -> 1200 | Y13: =X13*U13*O13 -> 15600
A14: data promo | B14: norte | C14: ap | D14: macapa | E14: Atos | F14: Outdoor lonado | H14: x | I14: 3 | K14: x | M14: 10 | N14: 20 | O14: 13 | P14: Mensal | S14: 13 | U14: 1 | V14: 1500 | W14: 0.2 | X14: =V14*(1-W14) -> 1200 | Y14: =X14*U14*O14 -> 15600
A16: ouro produto | B16: norte | C16: ap | D16: macapa | E16: Bureau de mídia | F16: Frontlight | H16: x | I16: 3 | K16: x | M16: 2 | N16: 3 | O16: 1 | P16: Mensal | Q16: 1 | U16: 1 | V16: 5200 | W16: 0.34 | X16: =V16*(1-W16) -> 3432 | Y16: =X16*U16*O16 -> 3432
A17: ouro produto | B17: norte | C17: ap | D17: macapa | E17: Bureau de mídia | F17: Painel de Led | H17: x | I17: 2 | L17: x | M17: 2 | N17: 4 | O17: 2 | P17: Mensal | Q17: 1 | U17: 1 | V17: 7800 | W17: 0.34 | X17: =V17*(1-W17) -> 5148 | Y17: =X17*U17*O17 -> 10296
A18: ouro produto | B18: norte | C18: ap | D18: macapa | E18: Atos | F18: Frontlight | H18: x | I18: 3 | K18: x | M18: 2 | N18: 4 | O18: 1 | P18: Mensal | Q18: 1 | U18: 1 | V18: 3500 | W18: 0.2 | X18: =V18*(1-W18) -> 2800 | Y18: =X18*U18*O18 -> 2800
A19: ouro produto | B19: norte | C19: ap | D19: macapa | E19: Atos | F19: Outdoor lonado | H19: x | I19: 1 | K19: x | M19: 8 | N19: 13 | O19: 8 | P19: Diaria | Q19: 1 | U19: 1 | V19: 1500 | W19: 0.2 | X19: =V19*(1-W19) -> 1200 | Y19: =X19*U19*O19 -> 9600
A20: ouro produto | B20: norte | C20: ap | D20: macapa | E20: Atos | F20: Outdoor lonado | H20: x | I20: 1 | K20: x | M20: 10 | N20: 25 | O20: 8 | P20: Mensal | Q20: 1 | U20: 1 | V20: 1500 | W20: 0.2 | X20: =V20*(1-W20) -> 1200 | Y20: =X20*U20*O20 -> 9600
A22: ouro promo | B22: norte | C22: ap | D22: macapa | E22: Bureau de mídia | F22: Painel de Led | H22: x | I22: 1 | L22: x | M22: 2 | N22: 4 | O22: 1 | P22: Mensal | Q22: 1 | U22: 1 | V22: 5200 | W22: 0.34 | X22: =V22*(1-W22) -> 3432 | Y22: =X22*U22*O22 -> 3432
A23: ouro promo | B23: norte | C23: ap | D23: macapa | E23: Bureau de mídia | F23: Busdoor | H23: x | I23: 2 | K23: x | M23: 5 | N23: 10 | O23: 1 | P23: Mensal | Q23: 1 | U23: 1 | V23: 7800 | W23: 0.34 | X23: =V23*(1-W23) -> 5148 | Y23: =X23*U23*O23 -> 5148
A24: ouro promo | B24: norte | C24: ap | D24: macapa | E24: Bureau de mídia | F24: Bikedoor | H24: x | I24: 5 | K24: x | M24: 2 | N24: 5 | O24: 3 | P24: Mensal | Q24: 3 | U24: 1 | V24: 1550 | W24: 0.2 | X24: =V24*(1-W24) -> 1240 | Y24: =X24*U24*O24 -> 3720
A25: ouro promo | B25: norte | C25: ap | D25: macapa | E25: Atos | F25: Frontlight | H25: x | I25: 4 | K25: x | M25: 2 | N25: 4 | O25: 4 | P25: Diaria | Q25: 4 | S25: 4 | U25: 2 | V25: 2450 | W25: 0.2 | X25: =V25*(1-W25) -> 1960 | Y25: =X25*U25*O25 -> 15680
A26: ouro promo | B26: norte | C26: ap | D26: macapa | E26: Atos | F26: Outdoor lonado | H26: x | I26: 3 | K26: x | M26: 8 | N26: 13 | O26: 1 | P26: Mensal | Q26: 1 | U26: 1 | V26: 3500 | W26: 0.2 | X26: =V26*(1-W26) -> 2800 | Y26: =X26*U26*O26 -> 2800
A27: ouro promo | B27: norte | C27: ap | D27: macapa | E27: Atos | F27: Outdoor lonado | H27: x | I27: 3 | K27: x | M27: 10 | N27: 25 | O27: 13 | P27: Mensal | Q27: 13 | U27: 1 | V27: 1500 | W27: 0.2 | X27: =V27*(1-W27) -> 1200 | Y27: =X27*U27*O27 -> 15600
A29: prata | B29: norte | C29: ap | D29: macapa | E29: Bureau de mídia | F29: Frontlight | H29: x | I29: 3 | K29: x | M29: 2 | N29: 3 | O29: 1 | P29: Mensal | Q29: 1 | U29: 1 | V29: 5200 | W29: 0.34 | X29: =V29*(1-W29) -> 3432 | Y29: =X29*U29*O29 -> 3432
A30: prata | B30: norte | C30: ap | D30: macapa | E30: Bureau de mídia | F30: Painel de Led | H30: x | I30: 1 | L30: x | M30: 2 | N30: 4 | O30: 1 | P30: Mensal | Q30: 1 | U30: 1 | V30: 7800 | W30: 0.34 | X30: =V30*(1-W30) -> 5148 | Y30: =X30*U30*O30 -> 5148
A31: prata | B31: norte | C31: ap | D31: macapa | E31: Atos | F31: Frontlight | H31: x | I31: 3 | K31: x | M31: 2 | N31: 4 | O31: 1 | P31: Mensal | Q31: 1 | U31: 1 | V31: 3500 | W31: 0.2 | X31: =V31*(1-W31) -> 2800 | Y31: =X31*U31*O31 -> 2800
A32: prata | B32: norte | C32: ap | D32: macapa | E32: Atos | F32: Outdoor lonado | H32: x | I32: 2 | K32: x | M32: 8 | N32: 13 | O32: 4 | P32: Mensal | Q32: 4 | U32: 1 | V32: 1500 | W32: 0.2 | X32: =V32*(1-W32) -> 1200 | Y32: =X32*U32*O32 -> 4800
A33: prata | B33: norte | C33: ap | D33: macapa | E33: Atos | F33: Outdoor lonado | H33: x | I33: 2 | K33: x | M33: 10 | N33: 25 | O33: 4 | P33: Mensal | Q33: 4 | U33: 1 | V33: 1500 | W33: 0.2 | X33: =V33*(1-W33) -> 1200 | Y33: =X33*U33*O33 -> 4800
E38: cpf mínimo | F38: cpf plano | G38: cpf máximo
A39: DATA PRODUTO | E39: =F39*(1-10%) -> 1567.5429 | F39: =MACAPA!T46 -> 1741.7143 | G39: =F39*(1+15%) -> 2002.9714
A40: DATA PROMO | E40: =F40*(1-25%) -> 1255.875 | F40: =MACAPA!T75 -> 1674.5 | G40: =F40*(1+5%) -> 1758.225
A41: OURO PRODUTO | E41: =F41*(1-15%) -> 1671.44 | F41: =MACAPA!T108 -> 1966.4 | G41: =F41*(1+15%) -> 2261.36
A42: OURO PROMO | E42: =F42*(1-25%) -> 1283.375 | F42: =MACAPA!T140 -> 1711.1667 | G42: =F42*(1+5%) -> 1796.725
A43: PRATA | E43: =F43*(1-25%) -> 1600.9091 | F43: =MACAPA!T172 -> 2134.5455 | G43: =F43*(1+5%) -> 2241.2727
E45: ranking semanas - distribuição investimento
A46: DATA PRODUTO | E46: 0.57 | F46: 0.43
A47: DATA PROMO | E47: 0.57 | F47: 0.43
A48: OURO PRODUTO | E48: 0.6 | F48: 0.4
A49: OURO PROMO | E49: 0.58 | F49: 0.42
...

Sheet MANAUS
A1: =[16]BASE!A2 -> ESTUDO MANAUS
A2: IBGE 2024/ CENSO 2022
A7: INVESTIMENTO MANAUS CAPITAL OOH 2024 | B7: 1306076
A8: INVESTIMENTO AMAZONAS OOH 2024 | B8: 1306076
A10: R$ BRUTO MANAUS CAPITAL - 2025 OOH | B10: 2219458.8
A11: BUDGET BRUTO AMAZONAS - 2025 OOH (100%) | B11: 2219458.8
A14: Exclusão de Bronze
A15: CICLOS/MEDALHAS | C15: % BUDGET/CICLO | D15: R$ MEDALHA | E15: R$ UNIT. MEDALHAS
A16: Data | B16: 3 - 2 produto/1 promo | C16: 0.39 | D16: 865588.91 | E16: 288529.64
A17: Ouro | B17: 5 - 4 produto/ 1 promo | C17: 0.4 | D17: 887783.5 | E17: 221945.88
A18: Prata | B18: 3 | C18: 0.21 | D18: 466086.34 | E18: 116521.58
B19: 11 ciclos | C19: 1 | D19: 2219458.8
A21: População Capital - 2.063.689 | B21: 2063689
A22: População Target - AS ABC 18/49 (logan) | B22: 1160368
E23: Cobertura total - Data Produto | F23: 47% | H23: Cobertura total - Data Promo | J23: 62%
E24: Frequencia | F24: 21 | H24: Frequencia | J24: 27
E25: TRP | F25: 1686 | H25: TRP | J25: 1686
E26: OTS | F26: 11.298.463 | H26: OTS | J26: 19.564.087
A27: Programação - Ciclo Data Produto
A29: 1 CICLO | T29: TOTAL ANO / CICLO
A30: Praça | B30: Exibidores | C30: Pen/Aff | D30: Canais | E30: Formato | F30: Range de volume ideal | G30: Qtdade | H30: Periodicidade | I30: Mês Base | M30: TT | N30: R$ Unit Bruto | O30: Desconto | P30: R$ Unit Bruto | Q30: R$ TT Bruto | R30: C.P.M. Formato | S30: % | T30: R$ Total | U30: AMBIENTES | Z30: FORMATO | AB30: EMPRESAS
I31: S1 | J31: S2 | K31: S3 | L31: S4 | M31: Flight | N31: Tabela | O31: (%) | P31: Negociado | Q31: Negociado | T31: ano
A32: DATAS MÃES/NATAL | U32: GDES | V32: MUB | W32: TRANSP | X32: AERO | Y32: OPORT | Z32: ESTÁTICO | AA32: DIGITAL | AB32: WEOOH | AC32: BME | AD32: THE VOICE | AE32: VSP | AF32: WVK | AG32: PURAKA | AH32: BUREAU | AI32: S2X
A34: Manaus - AM | B34: WeOOH | C34: 50/156 | D34: Painel de Led | E34: Digital | F34: 6/12 | G34: 1 | H34: Mensal | I34: 1 | M34: 1 | N34: 35211.99 | O34: 0.55 | P34: =N34*(1-O34) -> 15845.395 | Q34: =P34*M34*G34 -> 15845.395 | R34: =(Q34+Q35+Q38+#REF!)/E12*1000 -> #REF! | S34: =Q34/$Q$51 -> 0.054921098 | T34: =Q34*2 -> 31690.791 | U34: =T34 -> 31690.791 | AA34: =T34 -> 31690.791 | AB34: =T34 -> 31690.791
A35: Manaus - AM | B35: Brasil Midia Exterior | C35: 50/156 | D35: Painel de Led | E35: Digital | F35: 6/12 | G35: 1 | H35: Mensal | I35: 1 | M35: 1 | N35: 7000 | O35: 0.1 | P35: =N35*(1-O35) -> 6300 | Q35: =P35*M35*G35 -> 6300 | S35: =Q35/$Q$51 -> 0.02183618 | T35: =Q35*2 -> 12600 | U35: =T35 -> 12600 | AA35: =T35 -> 12600 | AC35: =T35 -> 12600
A36: Manaus - AM | B36: Brasil Midia Exterior | C36: 50/156 | D36: Frontlight | E36: Estático | F36: 7/14 | G36: 1 | H36: Bisemanal | I36: 1 | M36: 1 | N36: 7500 | O36: 0.1 | P36: =N36*(1-O36) -> 6750 | Q36: =P36*M36*G36 -> 6750 | R36: =(Q36+#REF!)/E12*1000 -> #REF! | S36: =Q36/$Q$51 -> 0.023395908 | T36: =Q36*2 -> 13500 | U36: =T36 -> 13500 | Z36: =T36 -> 13500 | AC36: =T36 -> 13500
A37: Manaus - AM | B37: Brasil Midia Exterior | C37: 50/156 | D37: Outdoor lonado | E37: Estático | F37: 16/25 | G37: 20 | H37: Mensal | I37: 20 | M37: 1 | N37: 2900 | O37: 0.1 | P37: =N37*(1-O37) -> 2610 | Q37: =P37*M37*G37 -> 52200 | R37: =(Q37+#REF!)/E12*1000 -> #REF! | S37: =Q37/$Q$51 -> 0.18092835 | T37: =Q37*2 -> 104400 | U37: =T37 -> 104400 | Z37: =T37 -> 104400 | AC37: =T36 -> 13500
A38: Manaus - AM | B38: The Voice | C38: 50/156 | D38: Painel de Led | E38: Digital | F38: 6/12 | G38: 1 | H38: Mensal | I38: 1 | M38: 1 | N38: 17576 | O38: 0.55 | P38: =N38*(1-O38) -> 7909.2 | Q38: =P38*M38*G38 -> 7909.2 | S38: =Q38/$Q$51 -> 0.027413765 | T38: =Q38*2 -> 15818.4 | U38: =T38 -> 15818.4 | AA38: =T38 -> 15818.4 | AD38: =T37 -> 104400
A39: Manaus - AM | B39: VSP Midia | C39: 50/156 | D39: Frontlight | E39: Estático | F39: 7/14 | G39: 1 | H39: Mensal | I39: 1 | M39: 1 | N39: 5500 | O39: 0.15 | P39: =N39*(1-O39) -> 4675 | Q39: =P39*M39*G39 -> 4675 | R39: =(Q39+#REF!+Q40)/E12*1000 -> #REF! | S39: =Q39/$Q$51 -> 0.016203832 | T39: =Q39*2 -> 9350 | U39: =T39 -> 9350 | Z39: =T39 -> 9350 | AE39: =T39 -> 9350
A40: Manaus - AM | B40: WVK midias | C40: 50/156 | D40: Outdoor lonado | E40: Estática | F40: 16/25 | G40: 20 | H40: Mensal | K40: 20 | M40: 1 | N40: 3222.65 | O40: 0.2 | P40: =N40*(1-O40) -> 2578.12 | Q40: =P40*M40*G40 -> 51562.4 | S40: =Q40/$Q$51 -> 0.17871839 | T40: =Q40*2 -> 103124.8 | U40: =T40 -> 103124.8 | Z40: =T40 -> 103124.8 | AF40: =T40 -> 103124.8
A41: Manaus - AM | B41: Puraka | C41: 50/155 | D41: Painel de Led | E41: Digital | F41: 6/12 | G41: 5 | H41: Mensal | I41: 5 | M41: 1 | N41: 12150 | O41: 0.4 | P41: =N41*(1-O41) -> 7290 | Q41: =P41*M41*G41 -> 36450 | S41: =Q41/$Q$51 -> 0.1263379 | T41: =Q41*2 -> 72900 | U41: =T41 -> 72900 | AA41: =T41 -> 72900 | AG41: =T41 -> 72900
A42: Manaus - AM | B42: Puraka | C42: 50/155 | D42: Frontlight | E42: Estático | F42: 7/14 | G42: 4 | H42: Mensal | I42: 4 | M42: 1 | N42: 15000 | O42: 0.49 | P42: =N42*(1-O42) -> 7650 | Q42: =P42*M42*G42 -> 30600 | S42: =Q42/$Q$51 -> 0.10606145 | T42: =Q42*2 -> 61200 | U42: =T42 -> 61200 | Z42: =T42 -> 61200 | AG42: =T42 -> 61200
A43: Manaus - AM | B43: Bureau Midia OOH | C43: 50/155 | D43: Painel de Led | E43: Digital | F43: 6/12 | G43: 2 | H43: Mensal | I43: 2 | M43: 1 | N43: 8980 | O43: 0.25 | P43: =N43*(1-O43) -> 6735 | Q43: =P43*M43*G43 -> 13470 | S43: =Q43/$Q$51 -> 0.046687833 | T43: =Q43*2 -> 26940 | U43: =T43 -> 26940 | AA43: =T43 -> 26940 | AH43: =T43 -> 26940
A44: Manaus - AM | B44: Bureau Midia OOH | C44: 50/155 | D44: Frontlight | E44: Estático | F44: 7/14 | G44: 2 | H44: Mensal | I44: 2 | M44: 1 | N44: 14500 | O44: 0.25 | P44: =N44*(1-O44) -> 10875 | Q44: =P44*M44*G44 -> 21750 | S44: =Q44/$Q$51 -> 0.075386814 | T44: =Q44*2 -> 43500 | U44: =T44 -> 43500 | Z44: =T44 -> 43500 | AH44: =T44 -> 43500
A48: Manaus - AM | B48: Aeroporto | Q48: =P48*M48*G48 -> 0 | S48: =Q48/Q51 -> 0 | T48: =Q48*2 -> 0 | X48: =T48 -> 0 | AA48: =X48 -> 0
A49: Manaus - AM | B49: Oportunidades | Q49: 41000 | S49: =Q49/Q51 -> 0.14210848 | T49: =Q49*2 -> 82000 | Y49: =T49 -> 82000
I50: =I51/M51 -> 0.55555556 | K50: =K51/M51 -> 0.44444444
