Workbook

Sheet BELEM
A1: ESTUDO BELEM
A2: IBGE 2024/ CENSO 2022
A7: INVESTIMENTO BELEM CAPITAL OOH 2024 | B7: 1641632.8
A8: INVESTIMENTO PARÁ OOH 2024 | B8: 2328715
A10: R$ BRUTO BELÉM CAPITAL - 2025 OOH | B10: 3295226.5
A11: BUDGET BRUTO PARÁ - 2025 OOH (100%) | B11: 4453008.8
A14: Exclusão de Bronze
A15: CICLOS/MEDALHAS | C15: % BUDGET/CICLO | D15: R$ MEDALHA | E15: R$ UNIT. MEDALHAS
A16: Datas | B16: 3 - 2 produto/1 promo | C16: 0.37 | D16: 1219233.8 | E16: 406411.27
A17: Ouro | B17: 5 - 4 produto/ 1 promo | C17: 0.4 | D17: 1318090.6 | E17: 329522.65
A18: Prata | B18: 3 | C18: 0.23 | D18: 757902.09 | E18: 189475.52
B19: 11 ciclos | C19: 1
A21: População Target - AS ABC 18/49 | B21: 584877
A22: Popuação Capital - 1.1303.403 | B22: 1103403
E24: Cobertura total - Data Produto | F24: 70% | H24: Cobertura total - Data Promo | J24: 0.73
E25: Frequencia | F25: 39 | H25: Frequencia | J25: 42
E26: TRP | F26: 2.623 | H26: TRP | J26: 3042
E27: OTS | F27: 15.338.810 | H27: OTS | J27: 17791934
A29: Programação - Ciclo Data Produto
A31: 1 CICLO | S31: TOTAL ANO / CLUSTER
A32: Praça | B32: Exibidores | C32: Pen/Aff | D32: Canais | E32: Formato | F32: Range de volume ideal | G32: Qtdade | H32: Periodicidade | I32: Mês Base | M32: TT | N32: R$ Unit Bruto | O32: Desconto | P32: R$ Unit Bruto | Q32: R$ TT Bruto | R32: % | S32: R$ Total | T32: AMBIENTES | Y32: FORMATO | AB32: EMPRESAS
I33: S1 | J33: S2 | K33: S3 | L33: S4 | M33: Flight | N33: Tabela | O33: (%) | P33: Negociado | Q33: Negociado | S33: ano
A34: DATAS MÃES/NATAL | T34: GDES | U34: MUB | V34: TRANSP | W34: AERO | X34: OPORT | Y34: ESTÁTICO | Z34: DIGITAL | AB34: ELETROMIDIA | AC34: WEOOH | AD34: BME | AE34: ULTRA OOH | AF34: GREEN OOH | AG34: S2X | AH34: PRISMA OOH | AI34: PURAKA | AJ34: BUREAU | AK34: KALLAS
A36: Belem - PA | B36: Eletromidia | C36: 50/156 | D36: Painel de Led | E36: Digital | F36: 6/12 | G36: 1 | H36: Semanal | I36: 1 | K36: 1 | M36: 1 | N36: 5929 | O36: 0.6 | P36: =N36*(1-O36) -> 2371.6 | Q36: =P36*M36*G36 -> 2371.6 | R36: =Q36/$Q$59 -> 0.0058381117 | S36: =Q36*2 -> 4743.2 | T36: =S36 -> 4743.2 | Z36: =S36 -> 4743.2 | AB36: =S36 -> 4743.2
A37: Belem - PA | B37: WeOOH | C37: 50/156 | D37: Painel de Led | E37: Digital | F37: 6/12 | G37: 1 | H37: Mensal | I37: 1 | M37: 1 | N37: 27024.15 | O37: 0.75 | P37: =N37*(1-O37) -> 6756.0375 | Q37: =P37*M37*G37 -> 6756.0375 | R37: =Q37/$Q$59 -> 0.016631178 | S37: =Q37*2 -> 13512.075 | T37: =S37 -> 13512.075 | Z37: =S37 -> 13512.075 | AC37: =S37 -> 13512.075
A38: Belem - PA | B38: Brasil Midia Exterior | C38: 50/156 | D38: Painel de Led | E38: Digital | F38: 6/12 | G38: 1 | H38: Mensal | I38: 1 | M38: 1 | N38: 7000 | O38: 0.1 | P38: =N38*(1-O38) -> 6300 | Q38: =P38*M38*G38 -> 6300 | R38: =Q38/$Q$59 -> 0.015508561 | S38: =Q38*2 -> 12600 | T38: =S38 -> 12600 | Z38: =S38 -> 12600 | AD38: =S38 -> 12600
A39: Belem - PA | B39: Brasil Midia Exterior | C39: 50/156 | D39: Frontlight | E39: Estático | F39: 4/8 | G39: 1 | H39: Mensal | I39: 1 | M39: 1 | N39: 7500 | O39: 0.1 | P39: =N39*(1-O39) -> 6750 | Q39: =P39*M39*G39 -> 6750 | R39: =Q39/$Q$59 -> 0.016616316 | S39: =Q39*2 -> 13500 | T39: =S39 -> 13500 | Y39: =S39 -> 13500 | AD39: =S39 -> 13500
A40: Belem - PA | B40: Brasil Midia Exterior | C40: 50/156 | D40: Outdoor lonado | E40: Estático | F40: 15/30 | G40: 25 | H40: Mensal | I40: 25 | M40: 1 | N40: 2650 | O40: 0.1 | P40: =N40*(1-O40) -> 2385 | Q40: =P40*M40*G40 -> 59625 | R40: =Q40/$Q$59 -> 0.14677745 | S40: =Q40*2 -> 119250 | T40: =S40 -> 119250 | Y40: =S40 -> 119250 | AD40: =S40 -> 119250
A41: Belem - PA | B41: Ultra OOH | C41: 50/156 | D41: Painel de Led | E41: Digital | F41: 6/12 | G41: 1 | H41: Mensal | I41: 1 | M41: 1 | N41: 5593 | O41: 0.25 | P41: =N41*(1-O41) -> 4194.75 | Q41: =P41*M41*G41 -> 4194.75 | R41: =Q41/$Q$59 -> 0.010326117 | S41: =Q41*2 -> 8389.5 | T41: =S41 -> 8389.5 | Z41: =S41 -> 8389.5 | AE41: =S41 -> 8389.5
A42: Belem - PA | B42: Ultra OOH | C42: 50/156 | D42: Frontlight | E42: Estático | F42: 4/8 | G42: 2 | H42: Mensal | I42: 2 | M42: 1 | N42: =(10000+6680)/2 -> 8340 | O42: 0.3 | P42: =N42*(1-O42) -> 5838 | Q42: =P42*M42*G42 -> 11676 | R42: =Q42/$Q$59 -> 0.028742534 | S42: =Q42*2 -> 23352 | T42: =S42 -> 23352 | Y42: =S42 -> 23352 | AE42: =S42 -> 23352
A43: Belem - PA | B43: Ultra OOH | C43: 50/156 | D43: Empena | E43: Estático | F43: 2/5 | G43: 3 | H43: Mensal | I43: 3 | M43: 1 | N43: =(13400+28000+16000)/3 -> 19133.333 | O43: 0.25 | P43: =N43*(1-O43) -> 14350 | Q43: =P43*M43*G43 -> 43050 | R43: =Q43/$Q$59 -> 0.10597517 | S43: =Q43*2 -> 86100 | T43: =S43 -> 86100 | Y43: =S43 -> 86100 | AE43: =S43 -> 86100
A44: Belem - PA | B44: Green Outdoor | C44: 50/156 | D44: Painel de Led | E44: Digital | F44: 6/12 | G44: 1 | H44: Mensal | I44: 1 | M44: 1 | N44: 2362 | O44: 0.2 | P44: =N44*(1-O44) -> 1889.6 | Q44: =P44*M44*G44 -> 1889.6 | R44: =Q44/$Q$59 -> 0.0046515837 | S44: =Q44*2 -> 3779.2 | T44: =S44 -> 3779.2 | Z44: =S44 -> 3779.2 | AF44: =S44 -> 3779.2
A45: Belem - PA | B45: Green Outdoor | C45: 50/156 | D45: Outdoor lonado | E45: Estática | F45: 15/30 | G45: 25 | H45: Mensal | K45: 25 | M45: 1 | N45: 2650 | O45: 0.2 | P45: =N45*(1-O45) -> 2120 | Q45: =P45*M45*G45 -> 53000 | R45: =Q45/$Q$59 -> 0.13046885 | S45: =Q45*2 -> 106000 | T45: =S45 -> 106000 | Y45: =S45 -> 106000 | AF45: =S45 -> 106000
A46: Belem - PA | B46: S2X Promoções | C46: 30/155 | D46: Carro de Som | E46: Som | F46: 7/30 | G46: 7 | H46: Diaria 8 horas | I46: 7 | K46: 7 | M46: 2 | N46: =265*8 -> 2120 | O46: 0.4 | P46: =N46*(1-O46) -> 1272 | Q46: =P46*M46*G46 -> 17808 | R46: =Q46/$Q$59 -> 0.043837533 | S46: =Q46*2 -> 35616 | T46: =S46 -> 35616 | AG46: =S46 -> 35616
A47: Belem - PA | B47: Prisma OOH | C47: 50/156 | D47: Painel de Led | E47: Digital | F47: 6/12 | G47: 2 | H47: Mensal | I47: 2 | M47: 1 | N47: 7920 | O47: 0.25 | P47: =N47*(1-O47) -> 5940 | Q47: =P47*M47*G47 -> 11880 | R47: =Q47/$Q$59 -> 0.029244716 | S47: =Q47*2 -> 23760 | T47: =S47 -> 23760 | Z47: =S47 -> 23760 | AH47: =S47 -> 23760
A48: Belem - PA | B48: Puraka | C48: 50/156 | D48: Painel de Led | E48: Digital | F48: 6/12 | G48: 2 | H48: Mensal | I48: 2 | M48: 1 | N48: 18500 | O48: 0.6 | P48: =N48*(1-O48) -> 7400 | Q48: =P48*M48*G48 -> 14800 | R48: =Q48/$Q$59 -> 0.036432811 | S48: =Q48*2 -> 29600 | T48: =S48 -> 29600 | Z48: =S48 -> 29600 | AI48: =S48 -> 29600
A49: Belem - PA | B49: Puraka | C49: 50/156 | D49: Frontlight | E49: Estático | F49: 4/8 | G49: 2 | H49: Mensal | I49: 2 | M49: 1 | N49: 20500 | O49: 0.58 | P49: =N49*(1-O49) -> 8610 | Q49: =P49*M49*G49 -> 17220 | R49: =Q49/$Q$59 -> 0.042390067 | S49: =Q49*2 -> 34440 | T49: =S49 -> 34440 | Y49: =S49 -> 34440 | AI49: =S49 -> 34440
A50: Belem - PA | B50: Bureau de Mídia | C50: 50/156 | D50: Painel de Led | E50: Digital | F50: 6/12 | G50: 1 | H50: Mensal | I50: 1 | M50: 1 | N50: 8125 | O50: 0.15 | P50: =N50*(1-O50) -> 6906.25 | Q50: =P50*M50*G50 -> 6906.25 | R50: =Q50/$Q$59 -> 0.017000953 | S50: =Q50*2 -> 13812.5 | T50: =S50 -> 13812.5 | Z50: =S50 -> 13812.5 | AJ50: =S50 -> 13812.5
A51: Belem - PA | B51: Bureau de Mídia | C51: 50/156 | D51: Envelopamento Barco | E51: Estático | F51: 1 | G51: 1 | H51: Mensal | I51: 1 | M51: 1 | N51: 73000 | O51: 0 | P51: =N51*(1-O51) -> 73000 | Q51: =P51*M51*G51 -> 73000 | R51: =Q51/$Q$59 -> 0.17970238 | S51: =Q51*2 -> 146000 | V51: =S51 -> 146000 | Z51: =S51 -> 146000 | AJ51: =S51 -> 146000
A56: Belem - PA | B56: Aeroporto | S56: =Q56*2 -> 0 | W56: =S56 -> 0
...

Sheet Pesos
A1: 1 | B1: 0.9
A2: 2 | B2: 0.8
A3: 3 | B3: 0.7
A4: 4 | B4: 0.6
A5: 5 | B5: 0.5
A6: 6 | B6: 0.4
A7: 7 | B7: 0.3
A8: 8 | B8: 0.2
A9: 9 | B9: 0.1
A10: 10 | B10: 0.05
A11: 11 | B11: 0.03
A12: 12 | B12: 0.02

Sheet BELEM PLAN
A1: ciclos | B1: regional_boticario | C1: uf | D1: praca | E1: exibidores | F1: formato | G1: ranking | H1: pesos | I1: estatico | J1: digital | K1: range_minimo | L1: range_maximo | M1: quantidade | N1: periodicidade | O1: s1 | P1: s2 | Q1: s3 | R1: s4 | S1: flight | T1: unitario_bruto_tabela | U1: desconto | V1: unitario_bruto_negociado | W1: total_bruto_negociado
A2: data produto | B2: norte | C2: pa | D2: belem | E2: eletromidia | F2: Painel de Led | G2: 2 | H2: =VLOOKUP(G2,Pesos!A:B,2,0) -> 0.8 | J2: X | K2: 6 | L2: 12 | M2: 1 | N2: semanal | O2: 1 | Q2: 1 | S2: 2 | T2: 5929 | U2: 0.6 | V2: =T2*(1-U2) -> 2371.6 | W2: =V2*S2*M2 -> 4743.2
A3: data produto | B3: norte | C3: pa | D3: belem | E3: WeOOH | F3: Painel de Led | G3: 2 | H3: =VLOOKUP(G3,Pesos!A:B,2,0) -> 0.8 | J3: X | K3: 6 | L3: 12 | M3: 1 | N3: Mensal | O3: 1 | S3: 1 | T3: 27024.1 | U3: 0.75 | V3: =T3*(1-U3) -> 6756.025 | W3: =V3*S3*M3 -> 6756.025
A4: data produto | B4: norte | C4: pa | D4: belem | E4: Brasil Midia Exterior | F4: Painel de Led | G4: 2 | H4: =VLOOKUP(G4,Pesos!A:B,2,0) -> 0.8 | J4: X | K4: 6 | L4: 12 | M4: 1 | N4: Mensal | O4: 1 | S4: 1 | T4: 7000 | U4: 0.1 | V4: =T4*(1-U4) -> 6300 | W4: =V4*S4*M4 -> 6300
A5: data produto | B5: norte | C5: pa | D5: belem | E5: Brasil Midia Exterior | F5: Frontlight | G5: 5 | H5: =VLOOKUP(G5,Pesos!A:B,2,0) -> 0.5 | I5: X | K5: 4 | L5: 8 | M5: 1 | N5: Mensal | O5: 1 | S5: 1 | T5: 7500 | U5: 0.1 | V5: =T5*(1-U5) -> 6750 | W5: =V5*S5*M5 -> 6750
A6: data produto | B6: norte | C6: pa | D6: belem | E6: Brasil Midia Exterior | F6: Outdoor lonado | G6: 1 | H6: =VLOOKUP(G6,Pesos!A:B,2,0) -> 0.9 | I6: X | K6: 15 | L6: 30 | M6: 25 | N6: Bisemanal | O6: 25 | S6: 1 | T6: 2650 | U6: 0.1 | V6: =T6*(1-U6) -> 2385 | W6: =V6*S6*M6 -> 59625
A7: data produto | B7: norte | C7: pa | D7: belem | E7: Ultra OOH | F7: Painel de Led | G7: 2 | H7: =VLOOKUP(G7,Pesos!A:B,2,0) -> 0.8 | J7: X | K7: 6 | L7: 12 | M7: 1 | N7: Mensal | O7: 1 | S7: 1 | T7: 5593 | U7: 0.25 | V7: =T7*(1-U7) -> 4194.75 | W7: =V7*S7*M7 -> 4194.75
A8: data produto | B8: norte | C8: pa | D8: belem | E8: Ultra OOH | F8: Frontlight | G8: 5 | H8: =VLOOKUP(G8,Pesos!A:B,2,0) -> 0.5 | I8: X | K8: 4 | L8: 8 | M8: 2 | N8: Mensal | O8: 2 | S8: 1 | T8: =(10000+6680)/2 -> 8340 | U8: 0.3 | V8: =T8*(1-U8) -> 5838 | W8: =V8*S8*M8 -> 11676
A9: data produto | B9: norte | C9: pa | D9: belem | E9: Ultra OOH | F9: Empena | G9: 4 | H9: =VLOOKUP(G9,Pesos!A:B,2,0) -> 0.6 | I9: X | K9: 2 | L9: 5 | M9: 3 | N9: Mensal | O9: 3 | S9: 1 | T9: =(13400+28000+16000)/3 -> 19133.333 | U9: 0.25 | V9: =T9*(1-U9) -> 14350 | W9: =V9*S9*M9 -> 43050
A10: data produto | B10: norte | C10: pa | D10: belem | E10: Green Outdoor | F10: Painel de Led | G10: 2 | H10: =VLOOKUP(G10,Pesos!A:B,2,0) -> 0.8 | J10: X | K10: 6 | L10: 12 | M10: 1 | N10: Mensal | O10: 1 | S10: 1 | T10: 2362 | U10: 0.2 | V10: =T10*(1-U10) -> 1889.6 | W10: =V10*S10*M10 -> 1889.6
A11: data produto | B11: norte | C11: pa | D11: belem | E11: Green Outdoor | F11: Outdoor lonado | G11: 1 | H11: =VLOOKUP(G11,Pesos!A:B,2,0) -> 0.9 | I11: X | K11: 15 | L11: 30 | M11: 25 | N11: Mensal | Q11: 25 | S11: 1 | T11: 2650 | U11: 0.2 | V11: =T11*(1-U11) -> 2120 | W11: =V11*S11*M11 -> 53000
A12: data produto | B12: norte | C12: pa | D12: belem | E12: S2X Promoções | F12: Carro de Som | G12: 6 | H12: =VLOOKUP(G12,Pesos!A:B,2,0) -> 0.4 | K12: 7 | L12: 30 | M12: 7 | N12: Diaria 8 horas | O12: 7 | Q12: 7 | S12: 2 | T12: =265*8 -> 2120 | U12: 0.4 | V12: =T12*(1-U12) -> 1272 | W12: =V12*S12*M12 -> 17808
A13: data produto | B13: norte | C13: pa | D13: belem | E13: Prisma OOH | F13: Painel de Led | G13: 2 | H13: =VLOOKUP(G13,Pesos!A:B,2,0) -> 0.8 | J13: X | K13: 6 | L13: 12 | M13: 2 | N13: Mensal | O13: 2 | S13: 1 | T13: 7920 | U13: 0.25 | V13: =T13*(1-U13) -> 5940 | W13: =V13*S13*M13 -> 11880
A14: data produto | B14: norte | C14: pa | D14: belem | E14: Puraka | F14: Painel de Led | G14: 2 | H14: =VLOOKUP(G14,Pesos!A:B,2,0) -> 0.8 | J14: X | K14: 6 | L14: 12 | M14: 2 | N14: Mensal | O14: 2 | S14: 1 | T14: 18500 | U14: 0.6 | V14: =T14*(1-U14) -> 7400 | W14: =V14*S14*M14 -> 14800
A15: data produto | B15: norte | C15: pa | D15: belem | E15: Puraka | F15: Frontlight | G15: 5 | H15: =VLOOKUP(G15,Pesos!A:B,2,0) -> 0.5 | I15: X | K15: 6 | L15: 12 | M15: 2 | N15: Mensal | O15: 2 | S15: 1 | T15: 20500 | U15: 0.58 | V15: =T15*(1-U15) -> 8610 | W15: =V15*S15*M15 -> 17220
A16: data produto | B16: norte | C16: pa | D16: belem | E16: Bureau de Mídia | F16: Painel de Led | G16: 2 | H16: =VLOOKUP(G16,Pesos!A:B,2,0) -> 0.8 | J16: X | K16: 6 | L16: 12 | M16: 1 | N16: Mensal | O16: 1 | S16: 1 | T16: 8125 | U16: 0.15 | V16: =T16*(1-U16) -> 6906.25 | W16: =V16*S16*M16 -> 6906.25
A17: data produto | B17: norte | C17: pa | D17: belem | E17: Bureau de Mídia | F17: Envelopamento Barco | G17: 3 | H17: =VLOOKUP(G17,Pesos!A:B,2,0) -> 0.7 | I17: X | K17: 1 | L17: 3 | M17: 1 | N17: Mensal | O17: 1 | S17: 1 | T17: 73000 | U17: 0 | V17: =T17*(1-U17) -> 73000 | W17: =V17*S17*M17 -> 73000
A19: data promo | B19: norte | C19: pa | D19: belem | E19: Eletromidia | F19: Painel de Led | G19: 1 | H19: =VLOOKUP(G19,Pesos!A:B,2,0) -> 0.9 | J19: x | K19: 6 | L19: 12 | M19: 1 | N19: Semanal | O19: 1 | Q19: 1 | S19: 1 | T19: 5929 | U19: 0.6 | V19: =T19*(1-U19) -> 2371.6 | W19: =V19*S19*M19 -> 2371.6
A20: data promo | B20: norte | C20: pa | D20: belem | E20: WeOOH | F20: Painel de Led | G20: 1 | H20: =VLOOKUP(G20,Pesos!A:B,2,0) -> 0.9 | J20: x | K20: 6 | L20: 12 | M20: 2 | N20: Mensal | O20: 2 | S20: 1 | T20: 27024.15 | U20: 0.75 | V20: =T20*(1-U20) -> 6756.0375 | W20: =V20*S20*M20 -> 13512.075
A21: data promo | B21: norte | C21: pa | D21: belem | E21: Brasil Midia Exterior | F21: Painel de Led | G21: 1 | H21: =VLOOKUP(G21,Pesos!A:B,2,0) -> 0.9 | J21: x | K21: 6 | L21: 12 | M21: 2 | N21: Mensal | O21: 2 | S21: 1 | T21: 7000 | U21: 0.1 | V21: =T21*(1-U21) -> 6300 | W21: =V21*S21*M21 -> 12600
A22: data promo | B22: norte | C22: pa | D22: belem | E22: Brasil Midia Exterior | F22: Frontlight | G22: 5 | H22: =VLOOKUP(G22,Pesos!A:B,2,0) -> 0.5 | I22: x | K22: 4 | L22: 8 | M22: 1 | N22: Mensal | O22: 1 | S22: 1 | T22: 7500 | U22: 0.1 | V22: =T22*(1-U22) -> 6750 | W22: =V22*S22*M22 -> 6750
A23: data promo | B23: norte | C23: pa | D23: belem | E23: Brasil Midia Exterior | F23: Outdoor lonado | G23: 2 | H23: =VLOOKUP(G23,Pesos!A:B,2,0) -> 0.8 | I23: x | K23: 15 | L23: 30 | M23: 30 | N23: Mensal | O23: 30 | S23: 1 | T23: 2650 | U23: 0.1 | V23: =T23*(1-U23) -> 2385 | W23: =V23*S23*M23 -> 71550
A24: data promo | B24: norte | C24: pa | D24: belem | E24: Ultra OOH | F24: Painel de Led | G24: 1 | H24: =VLOOKUP(G24,Pesos!A:B,2,0) -> 0.9 | J24: x | K24: 6 | L24: 12 | M24: 1 | N24: Mensal | O24: 1 | S24: 1 | T24: 5593 | U24: 0.25 | V24: =T24*(1-U24) -> 4194.75 | W24: =V24*S24*M24 -> 4194.75
A25: data promo | B25: norte | C25: pa | D25: belem | E25: Ultra OOH | F25: Frontlight | G25: 5 | H25: =VLOOKUP(G25,Pesos!A:B,2,0) -> 0.5 | I25: x | K25: 4 | L25: 8 | M25: 2 | N25: Mensal | O25: 2 | S25: 1 | T25: =(10000+6680)/2 -> 8340 | U25: 0.3 | V25: =T25*(1-U25) -> 5838 | W25: =V25*S25*M25 -> 11676
A26: data promo | B26: norte | C26: pa | D26: belem | E26: Green Outdoor | F26: Painel de Led | G26: 1 | H26: =VLOOKUP(G26,Pesos!A:B,2,0) -> 0.9 | J26: x | K26: 6 | L26: 12 | M26: 1 | N26: Mensal | O26: 1 | S26: 1 | T26: 2362 | U26: 0.2 | V26: =T26*(1-U26) -> 1889.6 | W26: =V26*S26*M26 -> 1889.6
A27: data promo | B27: norte | C27: pa | D27: belem | E27: Green Outdoor | F27: Outdoor lonado | G27: 2 | H27: =VLOOKUP(G27,Pesos!A:B,2,0) -> 0.8 | I27: x | K27: 15 | L27: 30 | M27: 30 | N27: Mensal | O27: 30 | S27: 1 | T27: 2650 | U27: 0.2 | V27: =T27*(1-U27) -> 2120 | W27: =V27*S27*M27 -> 63600
A28: data promo | B28: norte | C28: pa | D28: belem | E28: S2X Promoções | F28: Carro de Som | G28: 3 | H28: =VLOOKUP(G28,Pesos!A:B,2,0) -> 0.7 | I28: x | K28: 7 | L28: 30 | M28: 7 | N28: Diaria 8 horas | O28: 7 | S28: 1 | T28: =265*8 -> 2120 | U28: 0.4 | V28: =T28*(1-U28) -> 1272 | W28: =V28*S28*M28 -> 8904
A29: data promo | B29: norte | C29: pa | D29: belem | E29: Prisma OOH | F29: Painel de Led | G29: 1 | H29: =VLOOKUP(G29,Pesos!A:B,2,0) -> 0.9 | J29: x | K29: 6 | L29: 12 | M29: 2 | N29: Mensal | O29: 2 | S29: 1 | T29: 7920 | U29: 0.25 | V29: =T29*(1-U29) -> 5940 | W29: =V29*S29*M29 -> 11880
A30: data promo | B30: norte | C30: pa | D30: belem | E30: Puraka | F30: Painel de Led | G30: 1 | H30: =VLOOKUP(G30,Pesos!A:B,2,0) -> 0.9 | J30: x | K30: 6 | L30: 12 | M30: 3 | N30: Mensal | O30: 3 | S30: 1 | T30: 18500 | U30: 0.6 | V30: =T30*(1-U30) -> 7400 | W30: =V30*S30*M30 -> 22200
A31: data promo | B31: norte | C31: pa | D31: belem | E31: Puraka | F31: Frontlight | G31: 5 | H31: =VLOOKUP(G31,Pesos!A:B,2,0) -> 0.5 | I31: x | K31: 4 | L31: 8 | M31: 2 | N31: Mensal | O31: 2 | S31: 1 | T31: 20500 | U31: 0.58 | V31: =T31*(1-U31) -> 8610 | W31: =V31*S31*M31 -> 17220
A32: data promo | B32: norte | C32: pa | D32: belem | E32: Bureau de Mídia | F32: Painel de Led | G32: 1 | H32: =VLOOKUP(G32,Pesos!A:B,2,0) -> 0.9 | J32: x | K32: 6 | L32: 12 | M32: 2 | N32: Mensal | O32: 2 | S32: 1 | T32: 8125 | U32: 0.15 | V32: =T32*(1-U32) -> 6906.25 | W32: =V32*S32*M32 -> 13812.5
A33: data promo | B33: norte | C33: pa | D33: belem | E33: Bureau de Mídia | F33: BikeDoor | G33: 6 | H33: =VLOOKUP(G33,Pesos!A:B,2,0) -> 0.4 | I33: x | K33: 5 | L33: 10 | M33: 4 | N33: Diario | O33: 4 | P33: 4 | Q33: 4 | R33: 4 | S33: 4 | T33: 1944 | U33: 0.15 | V33: =T33*(1-U33) -> 1652.4 | W33: =V33*S33*M33 -> 26438.4
A34: data promo | B34: norte | C34: pa | D34: belem | E34: Cartaxi | F34: Taxi - vidro traseiro | G34: 4 | H34: =VLOOKUP(G34,Pesos!A:B,2,0) -> 0.6 | I34: x | K34: 10 | L34: 35 | M34: 20 | N34: Mensal | O34: 20 | S34: 1 | T34: 1600 | U34: 0.5 | V34: =T34*(1-U34) -> 800 | W34: =V34*S34*M34 -> 16000
A36: ouro produto | B36: norte | C36: pa | D36: belem | E36: WeOOH | F36: Painel de Led | G36: 2 | H36: =VLOOKUP(G36,Pesos!A:B,2,0) -> 0.8 | J36: x | K36: 4 | L36: 8 | M36: 1 | N36: Mensal | O36: 1 | S36: 1 | T36: 27024.15 | U36: 0.75 | V36: =T36*(1-U36) -> 6756.0375 | W36: =V36*S36*M36 -> 6756.0375
A37: ouro produto | B37: norte | C37: pa | D37: belem | E37: Brasil Midia Exterior | F37: Painel de Led | G37: 2 | H37: =VLOOKUP(G37,Pesos!A:B,2,0) -> 0.8 | J37: x | K37: 4 | L37: 8 | M37: 1 | N37: Mensal | O37: 1 | S37: 1 | T37: 7000 | U37: 0.1 | V37: =T37*(1-U37) -> 6300 | W37: =V37*S37*M37 -> 6300
A38: ouro produto | B38: norte | C38: pa | D38: belem | E38: Brasil Midia Exterior | F38: Frontlight | G38: 5 | H38: =VLOOKUP(G38,Pesos!A:B,2,0) -> 0.5 | I38: x | K38: 3 | L38: 6 | M38: 1 | N38: Mensal | O38: 1 | S38: 1 | T38: 7500 | U38: 0.1 | V38: =T38*(1-U38) -> 6750 | W38: =V38*S38*M38 -> 6750
A39: ouro produto | B39: norte | C39: pa | D39: belem | E39: Brasil Midia Exterior | F39: Outdoor lonado | G39: 1 | H39: =VLOOKUP(G39,Pesos!A:B,2,0) -> 0.9 | I39: x | K39: 10 | L39: 20 | M39: 18 | N39: Mensal | O39: 18 | S39: 1 | T39: 2650 | U39: 0.1 | V39: =T39*(1-U39) -> 2385 | W39: =V39*S39*M39 -> 42930
A40: ouro produto | B40: norte | C40: pa | D40: belem | E40: Ultra OOH | F40: Painel de Led | G40: 2 | H40: =VLOOKUP(G40,Pesos!A:B,2,0) -> 0.8 | J40: x | K40: 4 | L40: 8 | M40: 1 | N40: Mensal | O40: 1 | S40: 1 | T40: 5593 | U40: 0.25 | V40: =T40*(1-U40) -> 4194.75 | W40: =V40*S40*M40 -> 4194.75
A41: ouro produto | B41: norte | C41: pa | D41: belem | E41: Ultra OOH | F41: Frontlight | G41: 5 | H41: =VLOOKUP(G41,Pesos!A:B,2,0) -> 0.5 | I41: x | K41: 3 | L41: 6 | M41: 2 | N41: Mensal | O41: 2 | S41: 1 | T41: =(10000+6680)/2 -> 8340 | U41: 0.3 | V41: =T41*(1-U41) -> 5838 | W41: =V41*S41*M41 -> 11676
A42: ouro produto | B42: norte | C42: pa | D42: belem | E42: Ultra OOH | F42: Empena | G42: 4 | H42: =VLOOKUP(G42,Pesos!A:B,2,0) -> 0.6 | I42: x | K42: 1 | L42: 3 | M42: 3 | N42: Mensal | O42: 3 | S42: 1 | T42: =(13400+28000+16000)/3 -> 19133.333 | U42: 0.25 | V42: =T42*(1-U42) -> 14350 | W42: =V42*S42*M42 -> 43050
...

Sheet BOA VISTA
A1: ESTUDO BOA VISTA
A2: IBGE 2024/ CENSO 2022
A7: INVESTIMENTO BOA VISTA CAPITAL OOH 2024 | B7: 249713.29
A8: INVESTIMENTO RORAIMA OOH 2024 | B8: 249713.29
A10: R$ BRUTO BOA VISTA CAPITAL - 2025 OOH | B10: 657396.25
A11: BUDGET BRUTO RORAIMA 2025 OOH (100%) | B11: 657396.25
A14: Exclusão de Bronze
A15: CICLOS/MEDALHAS | C15: % BUDGET/CICLO | D15: R$ MEDALHA | E15: R$ UNIT. MEDALHAS
A16: Data | B16: 3 - 2 produto/1 promo | C16: 0.44 | D16: 289254.35 | E16: 96418.117
A17: Ouro | B17: 5 - 4 produto/ 1 promo | C17: 0.48 | D17: 315550.2 | E17: 63110.04
A18: Prata | B18: 2 | C18: 0.08 | D18: 52591.7 | E18: 26295.85
B19: 10 ciclos | C19: 1 | D19: 657396.25
A21: População Capital | B21: 413486
A22: População Target - AS ABC 18/49 (logan) | B22: 223605
E23: Cobertura total - Data Produto | F23: 39% | H23: Cobertura total - Data Promo | J23: 0.49
E24: Frequencia | F24: 26 | H24: Frequencia | J24: 35
E25: TRP | F25: 326 | H25: TRP | J25: 590
E26: OTS | F26: 1.345.892 | H26: OTS | J26: 2145987
A28: Programação - Ciclo Data Produto
A30: 1 CICLO | T30: TOTAL ANO / CICLO
A31: Praça | B31: Exibidores | C31: Pen/Aff | D31: Canais | E31: Formato | F31: Range de volume ideal | G31: Qtdade | H31: Periodicidade | I31: Mês Base | M31: TT | N31: R$ Unit Bruto | O31: Desconto | P31: R$ Unit Bruto | Q31: R$ TT Bruto | R31: C.P.M. Formato | S31: % | T31: R$ Total | U31: AMBIENTES | Z31: FORMATO | AB31: EMPRESAS
I32: S1 | J32: S2 | K32: S3 | L32: S4 | M32: Flight | N32: Tabela | O32: (%) | P32: Negociado | Q32: Negociado | T32: ano
A33: DATAS MÃES/NATAL | U33: GDES | V33: MUB | W33: TRANSP | X33: AERO | Y33: OPORT | Z33: ESTÁTICO | AA33: DIGITAL | AB33: M2 | AC33: TELAS PROMO | AD33: KALLAS
A35: Boa Vista - RR | B35: M2 comunicações | C35: 50/156 | D35: Frontlight | E35: Estático | F35: 3/5 | G35: 3 | H35: Mensal | I35: 3 | M35: 1 | N35: 4480 | O35: 0.2 | P35: =N35*(1-O35) -> 3584 | Q35: =P35*M35*G35 -> 10752 | R35: =(Q35+Q36+#REF!+#REF!)/E11*1000 -> #REF! | S35: =Q35/$Q$43 -> 0.25844911 | T35: =Q35*2 -> 21504 | U35: =T35 -> 21504 | AA35: =T35 -> 21504 | AB35: =T35 -> 21504
A36: Boa Vista - RR | B36: Telas Promo | C36: 50/156 | D36: Painel de Led | E36: Digital | F36: 2/4 | G36: 2 | H36: Mensal | I36: 2 | M36: 1 | N36: 5000 | O36: 0.25 | P36: =N36*(1-O36) -> 3750 | Q36: =P36*M36*G36 -> 7500 | R36: =(Q36+Q37+#REF!+#REF!)/E12*1000 -> #REF! | S36: =Q36/$Q$43 -> 0.18027979 | T36: =Q36*2 -> 15000 | U36: =T36 -> 15000 | Z36: =T36 -> 15000 | AC36: =T36 -> 15000
A37: Boa Vista - RR | B37: Telas Promo | C37: 50/156 | D37: Circuito interno Led | E37: Digital | F37: 1/2 | G37: 2 | H37: Mensal | I37: 2 | M37: 1 | N37: 5000 | O37: 0.25 | P37: =N37*(1-O37) -> 3750 | Q37: =P37*M37*G37 -> 7500 | S37: =Q37/$Q$43 -> 0.18027979 | T37: =Q37*2 -> 15000 | V37: =T37 -> 15000 | Z37: =T37 -> 15000 | AC37: =T37 -> 15000
A38: Boa Vista - RR | B38: Telas Promo | C38: 50/156 | D38: Frontlight | E38: Estático | F38: 3/5 | G38: 2 | H38: Mensal | I38: 2 | M38: 1 | N38: 5500 | O38: 0.25 | P38: =N38*(1-O38) -> 4125 | Q38: =P38*M38*G38 -> 8250 | S38: =Q38/$Q$43 -> 0.19830777 | T38: =Q38*2 -> 16500 | U38: =T38 -> 16500 | AA38: =T38 -> 16500 | AC38: =U38 -> 16500
AD39: =T39 -> 0
A40: Boa Vista - RR | B40: Aeroporto | T40: =Q40*2 -> 0 | X40: =T40 -> 0
A41: Boa Vista - RR | B41: Oportunidades | D41: Marítimos / Ativação | Q41: 7600 | S41: =Q41/Q43 -> 0.18268352 | T41: =Q41*2 -> 15200 | Y41: =T41 -> 15200
A43: Total faces compra | I43: =I38+I37+I36+I35 -> 9 | M43: =SUM(I43:L43) -> 9 | Q43: =SUM(Q35:Q42) -> 41602 | S43: =SUM(S35:S41) -> 1 | T43: =SUM(T35:T42) -> 83204 | U43: =SUM(U35:U41) -> 53004 | V43: =SUM(V35:V41) -> 15000 | W43: =SUM(W35:W41) -> 0 | X43: =SUM(X35:X41) -> 0 | Y43: =SUM(Y35:Y41) -> 15200 | Z43: =SUM(Z35:Z41) -> 30000 | AA43: =SUM(AA35:AA41) -> 38004 | AB43: =SUM(AB35:AB42) -> 21504 | AC43: =SUM(AC34:AC40) -> 46500 | AD43: =SUM(AD34:AD40) -> 0
A44: Total faces simulação | I44: =I38+I37+I36+I35 -> 9 | J44: =I38+I37+I36+I35 -> 9 | K44: =I38+I37+I36+I35 -> 9 | L44: =I38+I37+I36+I35 -> 9 | M44: =SUM(I44:L44) -> 36 | U44: =U43/T43 -> 0.63703668 | V44: =V43/T43 -> 0.18027979 | W44: =W43/T43 -> 0 | X44: =X43/T43 -> 0 | Y44: =Y43/T43 -> 0.18268352 | Z44: =Z43/T43 -> 0.36055959 | AA44: =AA43/T43 -> 0.45675689
A45: Grandes Formatos | Q45: =U43/2 -> 26502 | S45: =Q45/Q50 -> 0.63703668 | Y45: =SUM(U35:Y42) -> 83204 | Z45: =I36+I37 -> 4 | AA45: =I35+I38 -> 5
A46: MUB | Q46: =V43/2 -> 7500 | S46: =Q46/Q50 -> 0.18027979 | T46: =Q43/M43 -> 4622.4444 | U46: CPFACE | Z46: =Z45/M43 -> 0.44444444 | AA46: =AA45/M43 -> 0.55555556
A47: Transportes | Q47: =W43/2 -> 0 | S47: =Q47/Q50 -> 0 | Z47: SHARE FACES
A48: Oportunidades | Q48: =Y43/2 -> 7600 | S48: =Q48/Q50 -> 0.18268352
A49: Aeroporto | Q49: =X43/2 -> 0 | S49: =Q49/Q50 -> 0
Q50: =SUM(Q45:Q49) -> 41602 | S50: =SUM(S45:S49) -> 1
A52: Programação - Ciclo Data Promo
A54: 1 CICLO | T54: TOTAL ANO / CICLO
...

Sheet BOA VISTA PLAN
A1: taxonomia | B1: regional_boticario | C1: uf | D1: praca | E1: exibidores | F1: formato | G1: ranking | H1: pesos | I1: estatico | J1: digital | K1: range_minimo | L1: range_maximo | M1: quantidade | N1: periodicidade | O1: s1 | P1: s2 | Q1: s3 | R1: s4 | S1: flight | T1: unitario_bruto_tabela | U1: desconto | V1: unitario_bruto_negociado | W1: total_bruto_negociado
A2: data produto | B2: norte | C2: rr | D2: boa vista | E2: M2 comunicações | F2: Frontlight | G2: 1 | H2: =VLOOKUP(G2,Pesos!A:B,2,0) -> 0.9 | I2: x | K2: 3 | L2: 5 | M2: 3 | N2: Mensal | O2: 3 | Q2: 1 | S2: 1 | T2: 4480 | U2: 0.2 | V2: =T2*(1-U2) -> 3584 | W2: =V2*S2*M2 -> 10752
A3: data produto | B3: norte | C3: rr | D3: boa vista | E3: Telas Promo | F3: Painel de Led | G3: 2 | H3: =VLOOKUP(G3,Pesos!A:B,2,0) -> 0.8 | J3: X | K3: 2 | L3: 4 | M3: 2 | N3: Mensal | O3: 2 | S3: 1 | T3: 5000 | U3: 0.25 | V3: =T3*(1-U3) -> 3750 | W3: =V3*S3*M3 -> 7500
A4: data produto | B4: norte | C4: rr | D4: boa vista | E4: Telas Promo | F4: Circuito interno Led | G4: 3 | H4: =VLOOKUP(G4,Pesos!A:B,2,0) -> 0.7 | J4: X | K4: 1 | L4: 2 | M4: 2 | N4: Mensal | O4: 2 | S4: 1 | T4: 5000 | U4: 0.25 | V4: =T4*(1-U4) -> 3750 | W4: =V4*S4*M4 -> 7500
A5: data produto | B5: norte | C5: rr | D5: boa vista | E5: Telas Promo | F5: Frontlight | G5: 1 | H5: =VLOOKUP(G5,Pesos!A:B,2,0) -> 0.9 | I5: X | K5: 3 | L5: 5 | M5: 2 | N5: Mensal | O5: 2 | S5: 1 | T5: 5500 | U5: 0.25 | V5: =T5*(1-U5) -> 4125 | W5: =V5*S5*M5 -> 8250
A7: data promo | B7: norte | C7: rr | D7: boa vista | E7: M2 comunicações | F7: Frontlight | G7: 3 | H7: =VLOOKUP(G7,Pesos!A:B,2,0) -> 0.7 | I7: x | K7: 2 | L7: 3 | M7: 2 | N7: Mensal | O7: 2 | S7: 1 | T7: 4480 | U7: 0.2 | V7: =T7*(1-U7) -> 3584 | W7: =V7*S7*M7 -> 7168
A8: data promo | B8: norte | C8: rr | D8: boa vista | E8: Telas Promo | F8: Painel de Led | G8: 1 | H8: =VLOOKUP(G8,Pesos!A:B,2,0) -> 0.9 | J8: x | K8: 2 | L8: 4 | M8: 2 | N8: Mensal | O8: 2 | S8: 1 | T8: 5000 | U8: 0.25 | V8: =T8*(1-U8) -> 3750 | W8: =V8*S8*M8 -> 7500
A9: data promo | B9: norte | C9: rr | D9: boa vista | E9: Telas Promo | F9: Circuito interno Led | G9: 4 | H9: =VLOOKUP(G9,Pesos!A:B,2,0) -> 0.6 | J9: x | K9: 1 | L9: 2 | M9: 2 | N9: Mensal | O9: 2 | S9: 1 | T9: 5000 | U9: 0.25 | V9: =T9*(1-U9) -> 3750 | W9: =V9*S9*M9 -> 7500
A10: data promo | B10: norte | C10: rr | D10: boa vista | E10: Telas Promo | F10: Frontlight | G10: 3 | H10: =VLOOKUP(G10,Pesos!A:B,2,0) -> 0.7 | I10: x | K10: 1 | L10: 2 | M10: 1 | N10: Mensal | O10: 1 | S10: 1 | T10: 5500 | U10: 0.25 | V10: =T10*(1-U10) -> 4125 | W10: =V10*S10*M10 -> 4125
A11: data promo | B11: norte | C11: rr | D11: boa vista | E11: Cartaxi | F11: Vidro traseiro + interno | G11: 5 | H11: =VLOOKUP(G11,Pesos!A:B,2,0) -> 0.5 | I11: x | K11: 3 | L11: 8 | M11: 8 | N11: Mensal | O11: 8 | S11: 1 | T11: 1600 | U11: 0.7 | V11: =T11*(1-U11) -> 480 | W11: =V11*S11*M11 -> 3840
A12: data promo | B12: norte | C12: rr | D12: boa vista | E12: Telas Promo | F12: Busdoor | G12: 2 | H12: =VLOOKUP(G12,Pesos!A:B,2,0) -> 0.8 | I12: x | K12: 2 | L12: 5 | M12: 4 | N12: Mensal | O12: 4 | S12: 1 | T12: 2000 | U12: 0.45 | V12: =T12*(1-U12) -> 1100 | W12: =V12*S12*M12 -> 4400
A14: ouro produto | B14: norte | C14: rr | D14: boa vista | E14: M2 comunicações | F14: Frontlight | G14: 1 | H14: =VLOOKUP(G14,Pesos!A:B,2,0) -> 0.9 | I14: x | K14: 2 | L14: 3 | M14: 2 | N14: Mensal | O14: 2 | S14: 1 | T14: 4480 | U14: 0.2 | V14: =T14*(1-U14) -> 3584 | W14: =V14*S14*M14 -> 7168
A15: ouro produto | B15: norte | C15: rr | D15: boa vista | E15: Telas Promo | F15: Painel de Led | G15: 2 | H15: =VLOOKUP(G15,Pesos!A:B,2,0) -> 0.8 | J15: x | K15: 2 | L15: 4 | M15: 2 | N15: Mensal | O15: 2 | S15: 1 | T15: 5000 | U15: 0.25 | V15: =T15*(1-U15) -> 3750 | W15: =V15*S15*M15 -> 7500
A16: ouro produto | B16: norte | C16: rr | D16: boa vista | E16: Telas Promo | F16: Circuito interno Led | G16: 3 | H16: =VLOOKUP(G16,Pesos!A:B,2,0) -> 0.7 | J16: x | K16: 1 | L16: 2 | M16: 2 | N16: Mensal | O16: 2 | S16: 1 | T16: 5000 | U16: 0.25 | V16: =T16*(1-U16) -> 3750 | W16: =V16*S16*M16 -> 7500
A17: ouro produto | B17: norte | C17: rr | D17: boa vista | E17: Telas Promo | F17: Frontlight | G17: 1 | H17: =VLOOKUP(G17,Pesos!A:B,2,0) -> 0.9 | I17: x | K17: 1 | L17: 2 | M17: 1 | N17: Mensal | O17: 1 | S17: 1 | T17: 5500 | U17: 0.25 | V17: =T17*(1-U17) -> 4125 | W17: =V17*S17*M17 -> 4125
A19: ouro promo | B19: norte | C19: rr | D19: boa vista | E19: M2 comunicações | F19: Frontlight | G19: 3 | H19: =VLOOKUP(G19,Pesos!A:B,2,0) -> 0.7 | I19: x | K19: 2 | L19: 3 | M19: 1 | N19: Mensal | O19: 1 | S19: 1 | T19: 4480 | U19: 0.2 | V19: =T19*(1-U19) -> 3584 | W19: =V19*S19*M19 -> 3584
A20: ouro promo | B20: norte | C20: rr | D20: boa vista | E20: Telas Promo | F20: Painel de Led | G20: 1 | H20: =VLOOKUP(G20,Pesos!A:B,2,0) -> 0.9 | J20: x | K20: 2 | L20: 4 | M20: 2 | N20: Mensal | O20: 2 | S20: 1 | T20: 5000 | U20: 0.25 | V20: =T20*(1-U20) -> 3750 | W20: =V20*S20*M20 -> 7500
A21: ouro promo | B21: norte | C21: rr | D21: boa vista | E21: Telas Promo | F21: Circuito interno Led | G21: 4 | H21: =VLOOKUP(G21,Pesos!A:B,2,0) -> 0.6 | J21: x | K21: 1 | L21: 2 | M21: 2 | N21: Mensal | O21: 2 | S21: 1 | T21: 5000 | U21: 0.25 | V21: =T21*(1-U21) -> 3750 | W21: =V21*S21*M21 -> 7500
A22: ouro promo | B22: norte | C22: rr | D22: boa vista | E22: Telas Promo | F22: Frontlight | G22: 3 | H22: =VLOOKUP(G22,Pesos!A:B,2,0) -> 0.7 | I22: x | K22: 1 | L22: 2 | M22: 1 | N22: Mensal | O22: 1 | S22: 1 | T22: 5500 | U22: 0.25 | V22: =T22*(1-U22) -> 4125 | W22: =V22*S22*M22 -> 4125
A23: ouro promo | B23: norte | C23: rr | D23: boa vista | E23: Cartaxi | F23: Vidro traseiro + interno | G23: 5 | H23: =VLOOKUP(G23,Pesos!A:B,2,0) -> 0.5 | I23: x | K23: 3 | L23: 8 | M23: 6 | N23: Mensal | O23: 6 | S23: 1 | T23: 1600 | U23: 0.7 | V23: =T23*(1-U23) -> 480 | W23: =V23*S23*M23 -> 2880
A24: ouro promo | B24: norte | C24: rr | D24: boa vista | E24: Telas Promo | F24: Busdoor | G24: 2 | H24: =VLOOKUP(G24,Pesos!A:B,2,0) -> 0.8 | I24: x | K24: 2 | L24: 5 | M24: 3 | N24: Mensal | O24: 3 | S24: 1 | T24: 2000 | U24: 0.45 | V24: =T24*(1-U24) -> 1100 | W24: =V24*S24*M24 -> 3300
A26: prata | B26: norte | C26: rr | D26: boa vista | E26: M2 comunicações | F26: Frontlight | G26: 3 | H26: =VLOOKUP(G26,Pesos!A:B,2,0) -> 0.7 | I26: x | K26: 2 | L26: 3 | M26: 1 | N26: Mensal | O26: 1 | S26: 1 | T26: 4480 | U26: 0.2 | V26: =T26*(1-U26) -> 3584 | W26: =V26*S26*M26 -> 3584
A27: prata | B27: norte | C27: rr | D27: boa vista | E27: Telas Promo | F27: Painel de Led | G27: 1 | H27: =VLOOKUP(G27,Pesos!A:B,2,0) -> 0.9 | J27: x | K27: 2 | L27: 4 | M27: 1 | N27: Mensal | O27: 1 | S27: 1 | T27: 5000 | U27: 0.25 | V27: =T27*(1-U27) -> 3750 | W27: =V27*S27*M27 -> 3750
A28: prata | B28: norte | C28: rr | D28: boa vista | E28: Telas Promo | F28: Circuito interno Led | G28: 4 | H28: =VLOOKUP(G28,Pesos!A:B,2,0) -> 0.6 | J28: x | K28: 1 | L28: 2 | M28: 1 | N28: Mensal | O28: 1 | S28: 1 | T28: 5000 | U28: 0.25 | V28: =T28*(1-U28) -> 3750 | W28: =V28*S28*M28 -> 3750
A29: prata | B29: norte | C29: rr | D29: boa vista | E29: Telas Promo | F29: Frontlight | G29: 3 | H29: =VLOOKUP(G29,Pesos!A:B,2,0) -> 0.7 | I29: x | K29: 1 | L29: 2 | M29: 1 | N29: Mensal | O29: 1 | S29: 1 | T29: 5500 | U29: 0.25 | V29: =T29*(1-U29) -> 4125 | W29: =V29*S29*M29 -> 4125
A30: prata | B30: norte | C30: rr | D30: boa vista | E30: Cartaxi | F30: Vidro traseiro + interno | G30: 5 | H30: =VLOOKUP(G30,Pesos!A:B,2,0) -> 0.5 | I30: x | K30: 3 | L30: 8 | M30: 2 | N30: Mensal | O30: 2 | S30: 1 | T30: 1600 | U30: 0.7 | V30: =T30*(1-U30) -> 480 | W30: =V30*S30*M30 -> 960
A31: prata | B31: norte | C31: rr | D31: boa vista | E31: Telas Promo | F31: Busdoor | G31: 2 | H31: =VLOOKUP(G31,Pesos!A:B,2,0) -> 0.8 | I31: x | K31: 2 | L31: 5 | M31: 1 | N31: Mensal | O31: 1 | S31: 1 | T31: 2000 | U31: 0.45 | V31: =T31*(1-U31) -> 1100 | W31: =V31*S31*M31 -> 1100
E36: cpf mínimo | F36: cpf plano | G36: cpf máximo
A37: DATA PRODUTO | E37: =F37*(1-10%) -> 4160.2 | F37: ='BOA VISTA'!T46 -> 4622.4444 | G37: =F37*(1+15%) -> 5315.8111
A38: DATA PROMO | E38: =F38*(1-25%) -> 1663.1447 | F38: ='BOA VISTA'!T73 -> 2217.5263 | G38: =F38*(1+5%) -> 2328.4026
A39: OURO PRODUTO | E39: =F39*(1-15%) -> 3860.5786 | F39: ='BOA VISTA'!T102 -> 4541.8571 | G39: =F39*(1+15%) -> 5223.1357
A40: OURO PROMO | E40: =F40*(1-25%) -> 1719.45 | F40: ='BOA VISTA'!T133 -> 2292.6 | G40: =F40*(1+5%) -> 2407.23
A41: PRATA | E41: =F41*(1-25%) -> 2118.1071 | F41: ='BOA VISTA'!T167 -> 2824.1429 | G41: =F41*(1+5%) -> 2965.35
E43: ranking semanas - distribuição investimento
A44: DATA PRODUTO | E44: 1
A45: DATA PROMO | E45: 1
A46: OURO PRODUTO | E46: 1
A47: OURO PROMO | E47: 1
A48: PRATA | E48: 1
E52: ranking semanas - distribuição audiência
...

Sheet MACAPA
A1: ESTUDO MACAPA
A2: IBGE 2024/ CENSO 2022
A6: INVESTIMENTO MACAPA CAPITAL OOH 2024 | B6: 393739.8
A7: INVESTIMENTO AMAPA OOH 2024 | B7: 393739.8
A9: R$ BRUTO MACAPA CAPITAL - 2025 OOH | B9: 1077573.8
A10: BUDGET BRUTO AMAPA 2025 OOH (100%) | B10: 1077573.8
A13: Exclusão de Bronze
A14: CICLOS/MEDALHAS | C14: % BUDGET/CICLO | D14: R$ MEDALHA | E14: R$ UNIT. MEDALHAS
A15: Datas (c6/c16/c17) | B15: 3 - 2 produto/1 promo | C15: 0.44 | D15: 474132.45 | E15: 158044.15
A16: Ouro (c1/c4/c11/c13) | B16: 5 - 4 produto/ 1 promo | C16: 0.48 | D16: 517235.4 | E16: 103447.08
A17: Prata (c3/c8/c10/c14) | B17: 2 | C17: 0.08 | D17: 86205.9 | E17: 43102.95
B18: 10 ciclos | C18: 1 | D18: 1077573.8
A21: População Capital | B21: 442933
A22: População Target - AS ABC 18/49 (logan) | B22: 249133 | E22: Cobertura total - Data Produto | F22: 32% | H22: Cobertura total - Data Promo | J22: 0.34
E23: Frequencia | F23: 23 | H23: Frequencia | J23: 25
E24: TRP | F24: 697 | H24: TRP | J24: 735
E25: OTS | F25: 1.735.289 | H25: OTS | J25: 1831500
A27: Programação - Ciclo Data Produto
A29: 1 CICLO | T29: TOTAL ANO / CICLO
A30: Praça | B30: Exibidores | C30: Pen/Aff | D30: Canais | E30: Formato | F30: Range de volume ideal | G30: Qtdade | H30: Periodicidade | I30: Mês Base | M30: TT | N30: R$ Unit Bruto | O30: Desconto | P30: R$ Unit Bruto | Q30: R$ TT Bruto | R30: C.P.M. Formato | S30: % | T30: R$ Total | U30: AMBIENTES | Z30: FORMATO | AB30: EMPRESAS
I31: S1 | J31: S2 | K31: S3 | L31: S4 | M31: Flight | N31: Tabela | O31: (%) | P31: Negociado | Q31: Negociado | T31: ano
A32: DATAS MÃES/NATAL | U32: GDES | V32: MUB | W32: TRANSP | X32: AERO | Y32: OPORT | Z32: ESTÁTICO | AA32: DIGITAL | AB32: BUREAU | AC32: ATOS
A34: Macapá - AP | B34: Bureau de mídia | C34: 50/156 | D34: Frontlight | E34: Estático | F34: 2/3 | G34: 2 | H34: Mensal | I34: 2 | M34: 1 | N34: 5200 | O34: 0.34 | P34: =N34*(1-O34) -> 3432 | Q34: =P34*M34*G34 -> 6864 | R34: =(Q34+Q35+Q39+#REF!)/E7*1000 -> #REF! | S34: =Q34/$Q$43 -> 0.11259843 | T34: =Q34*2 -> 13728 | U34: =T34 -> 13728 | AA34: =T34 -> 13728 | AB34: =T34 -> 13728
A35: Macapá - AP | B35: Bureau de mídia | C35: 50/156 | D35: Painel de Led | E35: Digital | F35: 2/4 | G35: 2 | H35: Mensal | I35: 2 | M35: 1 | N35: 7800 | O35: 0.34 | P35: =N35*(1-O35) -> 5148 | Q35: =P35*M35*G35 -> 10296 | R35: =(Q35+Q38+#REF!+#REF!)/E8*1000 -> #REF! | S35: =Q35/$Q$43 -> 0.16889764 | T35: =Q35*2 -> 20592 | U35: =T35 -> 20592 | AA35: =T35 -> 20592 | AB35: =T35 -> 20592
A36: Macapá - AP | B36: Atos | C36: 50/156 | D36: Frontlight | E36: Estático | F36: 2/4 | G36: 1 | H36: Mensal | I36: 1 | M36: 1 | N36: 3500 | O36: 0.2 | P36: =N36*(1-O36) -> 2800 | Q36: =P36*M36*G36 -> 2800 | S36: =Q36/$Q$43 -> 0.045931759 | T36: =Q36*2 -> 5600 | U36: =T36 -> 5600 | AA36: =T36 -> 5600 | AC36: =T36 -> 5600
A37: Macapá - AP | B37: Atos | C37: 50/156 | D37: Outdoor lonado | E37: Estático | F37: 8/13 | G37: 15 | H37: Mensal | I37: 15 | M37: 1 | N37: 1500 | O37: 0.2 | P37: =N37*(1-O37) -> 1200 | Q37: =P37*M37*G37 -> 18000 | R37: =(Q37+#REF!)/E6*1000 -> #REF! | S37: =Q37/$Q$43 -> 0.29527559 | T37: =Q37*2 -> 36000 | U37: =T37 -> 36000 | Z37: =T37 -> 36000 | AC37: =T37 -> 36000
A38: Macapá - AP | B38: Atos | C38: 50/156 | D38: Outdoor lonado | E38: Estático | F38: 10/25 | G38: 15 | H38: Mensal | K38: 15 | M38: 1 | N38: 1500 | O38: 0.2 | P38: =N38*(1-O38) -> 1200 | Q38: =P38*M38*G38 -> 18000 | R38: =(Q38+#REF!)/E8*1000 -> #REF! | S38: =Q38/$Q$43 -> 0.29527559 | T38: =Q38*2 -> 36000 | U38: =T38 -> 36000 | Z38: =T38 -> 36000 | AC38: =T38 -> 36000
A40: Macapá- AP | B40: Aeroporto | X40: =T40 -> 0
A41: Macapá-AP | B41: Oportunidades | D41: Marítimos / Ativação | Q41: 5000 | S41: =Q41/Q43 -> 0.082020997 | T41: =Q41*2 -> 10000 | Y41: =T41 -> 10000
I42: =I43/M43 -> 0.57142857 | K42: =K43/M43 -> 0.42857143
A43: Total faces compra | I43: =I37+I36+I35+I34 -> 20 | K43: =K38 -> 15 | M43: =SUM(I43:L43) -> 35 | Q43: =SUM(Q34:Q42) -> 60960 | S43: =SUM(S34:S41) -> 1 | T43: =SUM(T34:T42) -> 121920 | U43: =SUM(U34:U41) -> 111920 | V43: =SUM(V34:V41) -> 0 | W43: =SUM(W34:W41) -> 0 | X43: =SUM(X34:X41) -> 0 | Y43: =SUM(Y34:Y41) -> 10000 | Z43: =SUM(Z34:Z41) -> 72000 | AA43: =SUM(AA34:AA41) -> 39920 | AB43: =SUM(AB34:AB42) -> 34320 | AC43: =SUM(AC34:AC42) -> 77600
A44: Total faces simulação | I44: =I37+I36+I35+I34 -> 20 | J44: =I37+I36+I35+I34 -> 20 | K44: =K38+I36+I35+I34 -> 20 | L44: =K38+I36+I35+I34 -> 20 | M44: =SUM(I44:L44) -> 80 | U44: =U43/T43 -> 0.917979 | V44: =V43/T43 -> 0 | W44: =W43/T43 -> 0 | X44: =X43/T43 -> 0 | Y44: =Y43/T43 -> 0.082020997 | Z44: =Z43/T43 -> 0.59055118 | AA44: =AA43/T43 -> 0.32742782
A45: Grandes Formatos | Q45: =U43/2 -> 55960 | S45: =Q45/Q50 -> 0.917979 | Z45: =I34+I36+I37+K38 -> 33 | AA45: =I35 -> 2
A46: MUB | Q46: =V43/2 -> 0 | S46: =Q46/Q50 -> 0 | T46: =Q43/M43 -> 1741.7143 | U46: CPFACE | Z46: =Z45/M43 -> 0.94285714 | AA46: =AA45/M43 -> 0.057142857
A47: Transportes | Q47: =W43/2 -> 0 | S47: =Q47/Q50 -> 0 | Z47: SHARE FACES
A48: Oportunidades | Q48: =Y43/2 -> 5000 | S48: =Q48/Q50 -> 0.082020997
A49: Aeroporto | Q49: =X43/2 -> 0 | S49: =Q49/Q50 -> 0
Q50: =SUM(Q45:Q49) -> 60960 | S50: =SUM(S45:S49) -> 1
A52: Programação - Ciclo Data Promo
A54: 1 CICLO | T54: TOTAL ANO / CICLO
...

Sheet MACAPA PLAN
A1: taxonomia | B1: regional_boticario | C1: uf | D1: praca | E1: exibidores | F1: formato | G1: ranking | H1: pesos | I1: estatico | J1: digital | K1: range_minimo | L1: range_maximo | M1: quantidade | N1: periodicidade | O1: s1 | P1: s2 | Q1: s3 | R1: s4 | S1: flight | T1: unitario_bruto_tabela | U1: desconto | V1: unitario_bruto_negociado | W1: total_bruto_negociado
A2: data produto | B2: norte | C2: ap | D2: macapa | E2: Bureau de mídia | F2: Frontlight | G2: 3 | H2: =VLOOKUP(G2,Pesos!A:B,2,0) -> 0.7 | I2: x | K2: 2 | L2: 3 | M2: 2 | N2: Mensal | O2: 2 | Q2: 1 | S2: 1 | T2: 5200 | U2: 0.34 | V2: =T2*(1-U2) -> 3432 | W2: =V2*S2*M2 -> 6864
A3: data produto | B3: norte | C3: ap | D3: macapa | E3: Bureau de mídia | F3: Painel de Led | G3: 2 | H3: =VLOOKUP(G3,Pesos!A:B,2,0) -> 0.8 | J3: X | K3: 2 | L3: 4 | M3: 2 | N3: Mensal | O3: 2 | S3: 1 | T3: 7800 | U3: 0.34 | V3: =T3*(1-U3) -> 5148 | W3: =V3*S3*M3 -> 10296
A4: data produto | B4: norte | C4: ap | D4: macapa | E4: Atos | F4: Frontlight | G4: 3 | H4: =VLOOKUP(G4,Pesos!A:B,2,0) -> 0.7 | I4: x | K4: 2 | L4: 4 | M4: 1 | N4: Mensal | O4: 1 | S4: 1 | T4: 3500 | U4: 0.2 | V4: =T4*(1-U4) -> 2800 | W4: =V4*S4*M4 -> 2800
A5: data produto | B5: norte | C5: ap | D5: macapa | E5: Atos | F5: Outdoor lonado | G5: 1 | H5: =VLOOKUP(G5,Pesos!A:B,2,0) -> 0.9 | I5: X | K5: 10 | L5: 20 | M5: 15 | N5: Mensal | O5: 15 | S5: 1 | T5: 1500 | U5: 0.2 | V5: =T5*(1-U5) -> 1200 | W5: =V5*S5*M5 -> 18000
A6: data produto | B6: norte | C6: ap | D6: macapa | E6: Atos | F6: Outdoor lonado | G6: 1 | H6: =VLOOKUP(G6,Pesos!A:B,2,0) -> 0.9 | I6: x | K6: 10 | L6: 20 | M6: 15 | N6: Mensal | Q6: 15 | S6: 1 | T6: 1500 | U6: 0.2 | V6: =T6*(1-U6) -> 1200 | W6: =V6*S6*M6 -> 18000
A8: data promo | B8: norte | C8: ap | D8: macapa | E8: Bureau de mídia | F8: Frontlight | G8: 4 | H8: =VLOOKUP(G8,Pesos!A:B,2,0) -> 0.6 | I8: x | K8: 2 | L8: 3 | M8: 1 | N8: Mensal | O8: 1 | S8: 1 | T8: 5200 | U8: 0.34 | V8: =T8*(1-U8) -> 3432 | W8: =V8*S8*M8 -> 3432
A9: data promo | B9: norte | C9: ap | D9: macapa | E9: Bureau de mídia | F9: Painel de Led | G9: 1 | H9: =VLOOKUP(G9,Pesos!A:B,2,0) -> 0.9 | J9: x | K9: 2 | L9: 4 | M9: 1 | N9: Mensal | O9: 1 | S9: 1 | T9: 7800 | U9: 0.34 | V9: =T9*(1-U9) -> 5148 | W9: =V9*S9*M9 -> 5148
A10: data promo | B10: norte | C10: ap | D10: macapa | E10: Bureau de mídia | F10: Busdoor | G10: 2 | H10: =VLOOKUP(G10,Pesos!A:B,2,0) -> 0.8 | I10: x | K10: 5 | L10: 10 | M10: 3 | N10: Mensal | O10: 3 | S10: 1 | T10: 1550 | U10: 0.2 | V10: =T10*(1-U10) -> 1240 | W10: =V10*S10*M10 -> 3720
A11: data promo | B11: norte | C11: ap | D11: macapa | E11: Bureau de mídia | F11: Bikedoor | G11: 5 | H11: =VLOOKUP(G11,Pesos!A:B,2,0) -> 0.5 | I11: x | K11: 2 | L11: 5 | M11: 4 | N11: Diaria | O11: 4 | Q11: 4 | S11: 2 | T11: 2450 | U11: 0.2 | V11: =T11*(1-U11) -> 1960 | W11: =V11*S11*M11 -> 15680
A12: data promo | B12: norte | C12: ap | D12: macapa | E12: Atos | F12: Frontlight | G12: 4 | H12: =VLOOKUP(G12,Pesos!A:B,2,0) -> 0.6 | I12: x | K12: 2 | L12: 4 | M12: 1 | N12: Mensal | O12: 1 | S12: 1 | T12: 3500 | U12: 0.2 | V12: =T12*(1-U12) -> 2800 | W12: =V12*S12*M12 -> 2800
A13: data promo | B13: norte | C13: ap | D13: macapa | E13: Atos | F13: Outdoor lonado | G13: 3 | H13: =VLOOKUP(G13,Pesos!A:B,2,0) -> 0.7 | I13: x | K13: 10 | L13: 20 | M13: 13 | N13: Mensal | O13: 13 | S13: 1 | T13: 1500 | U13: 0.2 | V13: =T13*(1-U13) -> 1200 | W13: =V13*S13*M13 -> 15600
A14: data promo | B14: norte | C14: ap | D14: macapa | E14: Atos | F14: Outdoor lonado | G14: 3 | H14: =VLOOKUP(G14,Pesos!A:B,2,0) -> 0.7 | I14: x | K14: 10 | L14: 20 | M14: 13 | N14: Mensal | Q14: 13 | S14: 1 | T14: 1500 | U14: 0.2 | V14: =T14*(1-U14) -> 1200 | W14: =V14*S14*M14 -> 15600
A16: ouro produto | B16: norte | C16: ap | D16: macapa | E16: Bureau de mídia | F16: Frontlight | G16: 3 | H16: =VLOOKUP(G16,Pesos!A:B,2,0) -> 0.7 | I16: x | K16: 2 | L16: 3 | M16: 1 | N16: Mensal | O16: 1 | S16: 1 | T16: 5200 | U16: 0.34 | V16: =T16*(1-U16) -> 3432 | W16: =V16*S16*M16 -> 3432
A17: ouro produto | B17: norte | C17: ap | D17: macapa | E17: Bureau de mídia | F17: Painel de Led | G17: 2 | H17: =VLOOKUP(G17,Pesos!A:B,2,0) -> 0.8 | J17: x | K17: 2 | L17: 4 | M17: 2 | N17: Mensal | O17: 1 | S17: 1 | T17: 7800 | U17: 0.34 | V17: =T17*(1-U17) -> 5148 | W17: =V17*S17*M17 -> 10296
A18: ouro produto | B18: norte | C18: ap | D18: macapa | E18: Atos | F18: Frontlight | G18: 3 | H18: =VLOOKUP(G18,Pesos!A:B,2,0) -> 0.7 | I18: x | K18: 2 | L18: 4 | M18: 1 | N18: Mensal | O18: 1 | S18: 1 | T18: 3500 | U18: 0.2 | V18: =T18*(1-U18) -> 2800 | W18: =V18*S18*M18 -> 2800
A19: ouro produto | B19: norte | C19: ap | D19: macapa | E19: Atos | F19: Outdoor lonado | G19: 1 | H19: =VLOOKUP(G19,Pesos!A:B,2,0) -> 0.9 | I19: x | K19: 8 | L19: 13 | M19: 8 | N19: Diaria | O19: 1 | S19: 1 | T19: 1500 | U19: 0.2 | V19: =T19*(1-U19) -> 1200 | W19: =V19*S19*M19 -> 9600
A20: ouro produto | B20: norte | C20: ap | D20: macapa | E20: Atos | F20: Outdoor lonado | G20: 1 | H20: =VLOOKUP(G20,Pesos!A:B,2,0) -> 0.9 | I20: x | K20: 10 | L20: 25 | M20: 8 | N20: Mensal | O20: 1 | S20: 1 | T20: 1500 | U20: 0.2 | V20: =T20*(1-U20) -> 1200 | W20: =V20*S20*M20 -> 9600
A22: ouro promo | B22: norte | C22: ap | D22: macapa | E22: Bureau de mídia | F22: Painel de Led | G22: 1 | H22: =VLOOKUP(G22,Pesos!A:B,2,0) -> 0.9 | J22: x | K22: 2 | L22: 4 | M22: 1 | N22: Mensal | O22: 1 | S22: 1 | T22: 5200 | U22: 0.34 | V22: =T22*(1-U22) -> 3432 | W22: =V22*S22*M22 -> 3432
A23: ouro promo | B23: norte | C23: ap | D23: macapa | E23: Bureau de mídia | F23: Busdoor | G23: 2 | H23: =VLOOKUP(G23,Pesos!A:B,2,0) -> 0.8 | I23: x | K23: 5 | L23: 10 | M23: 1 | N23: Mensal | O23: 1 | S23: 1 | T23: 7800 | U23: 0.34 | V23: =T23*(1-U23) -> 5148 | W23: =V23*S23*M23 -> 5148
A24: ouro promo | B24: norte | C24: ap | D24: macapa | E24: Bureau de mídia | F24: Bikedoor | G24: 5 | H24: =VLOOKUP(G24,Pesos!A:B,2,0) -> 0.5 | I24: x | K24: 2 | L24: 5 | M24: 3 | N24: Mensal | O24: 3 | S24: 1 | T24: 1550 | U24: 0.2 | V24: =T24*(1-U24) -> 1240 | W24: =V24*S24*M24 -> 3720
A25: ouro promo | B25: norte | C25: ap | D25: macapa | E25: Atos | F25: Frontlight | G25: 4 | H25: =VLOOKUP(G25,Pesos!A:B,2,0) -> 0.6 | I25: x | K25: 2 | L25: 4 | M25: 4 | N25: Diaria | O25: 4 | Q25: 4 | S25: 2 | T25: 2450 | U25: 0.2 | V25: =T25*(1-U25) -> 1960 | W25: =V25*S25*M25 -> 15680
A26: ouro promo | B26: norte | C26: ap | D26: macapa | E26: Atos | F26: Outdoor lonado | G26: 3 | H26: =VLOOKUP(G26,Pesos!A:B,2,0) -> 0.7 | I26: x | K26: 8 | L26: 13 | M26: 1 | N26: Mensal | O26: 1 | S26: 1 | T26: 3500 | U26: 0.2 | V26: =T26*(1-U26) -> 2800 | W26: =V26*S26*M26 -> 2800
A27: ouro promo | B27: norte | C27: ap | D27: macapa | E27: Atos | F27: Outdoor lonado | G27: 3 | H27: =VLOOKUP(G27,Pesos!A:B,2,0) -> 0.7 | I27: x | K27: 10 | L27: 25 | M27: 13 | N27: Mensal | O27: 13 | S27: 1 | T27: 1500 | U27: 0.2 | V27: =T27*(1-U27) -> 1200 | W27: =V27*S27*M27 -> 15600
A29: prata | B29: norte | C29: ap | D29: macapa | E29: Bureau de mídia | F29: Frontlight | G29: 3 | H29: =VLOOKUP(G29,Pesos!A:B,2,0) -> 0.7 | I29: x | K29: 2 | L29: 3 | M29: 1 | N29: Mensal | O29: 1 | S29: 1 | T29: 5200 | U29: 0.34 | V29: =T29*(1-U29) -> 3432 | W29: =V29*S29*M29 -> 3432
A30: prata | B30: norte | C30: ap | D30: macapa | E30: Bureau de mídia | F30: Painel de Led | G30: 1 | H30: =VLOOKUP(G30,Pesos!A:B,2,0) -> 0.9 | J30: x | K30: 2 | L30: 4 | M30: 1 | N30: Mensal | O30: 1 | S30: 1 | T30: 7800 | U30: 0.34 | V30: =T30*(1-U30) -> 5148 | W30: =V30*S30*M30 -> 5148
A31: prata | B31: norte | C31: ap | D31: macapa | E31: Atos | F31: Frontlight | G31: 3 | H31: =VLOOKUP(G31,Pesos!A:B,2,0) -> 0.7 | I31: x | K31: 2 | L31: 4 | M31: 1 | N31: Mensal | O31: 1 | S31: 1 | T31: 3500 | U31: 0.2 | V31: =T31*(1-U31) -> 2800 | W31: =V31*S31*M31 -> 2800
A32: prata | B32: norte | C32: ap | D32: macapa | E32: Atos | F32: Outdoor lonado | G32: 2 | H32: =VLOOKUP(G32,Pesos!A:B,2,0) -> 0.8 | I32: x | K32: 8 | L32: 13 | M32: 4 | N32: Mensal | O32: 4 | S32: 1 | T32: 1500 | U32: 0.2 | V32: =T32*(1-U32) -> 1200 | W32: =V32*S32*M32 -> 4800
A33: prata | B33: norte | C33: ap | D33: macapa | E33: Atos | F33: Outdoor lonado | G33: 2 | H33: =VLOOKUP(G33,Pesos!A:B,2,0) -> 0.8 | I33: x | K33: 10 | L33: 25 | M33: 4 | N33: Mensal | O33: 4 | S33: 1 | T33: 1500 | U33: 0.2 | V33: =T33*(1-U33) -> 1200 | W33: =V33*S33*M33 -> 4800
E38: cpf mínimo | F38: cpf plano | G38: cpf máximo
A39: DATA PRODUTO | E39: =F39*(1-10%) -> 1567.5429 | F39: =MACAPA!T46 -> 1741.7143 | G39: =F39*(1+15%) -> 2002.9714
A40: DATA PROMO | E40: =F40*(1-25%) -> 1255.875 | F40: =MACAPA!T75 -> 1674.5 | G40: =F40*(1+5%) -> 1758.225
A41: OURO PRODUTO | E41: =F41*(1-15%) -> 1671.44 | F41: =MACAPA!T108 -> 1966.4 | G41: =F41*(1+15%) -> 2261.36
A42: OURO PROMO | E42: =F42*(1-25%) -> 1283.375 | F42: =MACAPA!T140 -> 1711.1667 | G42: =F42*(1+5%) -> 1796.725
A43: PRATA | E43: =F43*(1-25%) -> 1600.9091 | F43: =MACAPA!T172 -> 2134.5455 | G43: =F43*(1+5%) -> 2241.2727
E45: ranking semanas - distribuição investimento
A46: DATA PRODUTO | E46: 0.57 | G46: 0.43
A47: DATA PROMO | E47: 0.57 | G47: 0.43
A48: OURO PRODUTO | E48: 0.6 | G48: 0.4
A49: OURO PROMO | E49: 0.58 | G49: 0.42
...

Sheet MANAUS
A1: ESTUDO MANAUS
A2: IBGE 2024/ CENSO 2022
A7: INVESTIMENTO MANAUS CAPITAL OOH 2024 | B7: 1306076
A8: INVESTIMENTO AMAZONAS OOH 2024 | B8: 1306076
A10: R$ BRUTO MANAUS CAPITAL - 2025 OOH | B10: 2219458.8
A11: BUDGET BRUTO AMAZONAS - 2025 OOH (100%) | B11: 2219458.8
A14: Exclusão de Bronze
A15: CICLOS/MEDALHAS | C15: % BUDGET/CICLO | D15: R$ MEDALHA | E15: R$ UNIT. MEDALHAS
A16: Data | B16: 3 - 2 produto/1 promo | C16: 0.39 | D16: 865588.91 | E16: 288529.64
A17: Ouro | B17: 5 - 4 produto/ 1 promo | C17: 0.4 | D17: 887783.5 | E17: 221945.88
A18: Prata | B18: 3 | C18: 0.21 | D18: 466086.34 | E18: 116521.58
B19: 11 ciclos | C19: 1 | D19: 2219458.8
A21: População Capital - 2.063.689 | B21: 2063689
A22: População Target - AS ABC 18/49 (logan) | B22: 1160368
E23: Cobertura total - Data Produto | F23: 47% | H23: Cobertura total - Data Promo | J23: 62%
E24: Frequencia | F24: 21 | H24: Frequencia | J24: 27
E25: TRP | F25: 1686 | H25: TRP | J25: 1686
E26: OTS | F26: 11.298.463 | H26: OTS | J26: 19.564.087
A27: Programação - Ciclo Data Produto
A29: 1 CICLO | T29: TOTAL ANO / CICLO
A30: Praça | B30: Exibidores | C30: Pen/Aff | D30: Canais | E30: Formato | F30: Range de volume ideal | G30: Qtdade | H30: Periodicidade | I30: Mês Base | M30: TT | N30: R$ Unit Bruto | O30: Desconto | P30: R$ Unit Bruto | Q30: R$ TT Bruto | R30: C.P.M. Formato | S30: % | T30: R$ Total | U30: AMBIENTES | Z30: FORMATO | AB30: EMPRESAS
I31: S1 | J31: S2 | K31: S3 | L31: S4 | M31: Flight | N31: Tabela | O31: (%) | P31: Negociado | Q31: Negociado | T31: ano
A32: DATAS MÃES/NATAL | U32: GDES | V32: MUB | W32: TRANSP | X32: AERO | Y32: OPORT | Z32: ESTÁTICO | AA32: DIGITAL | AB32: WEOOH | AC32: BME | AD32: THE VOICE | AE32: VSP | AF32: WVK | AG32: PURAKA | AH32: BUREAU | AI32: S2X
A34: Manaus - AM | B34: WeOOH | C34: 50/156 | D34: Painel de Led | E34: Digital | F34: 6/12 | G34: 1 | H34: Mensal | I34: 1 | M34: 1 | N34: 35211.99 | O34: 0.55 | P34: =N34*(1-O34) -> 15845.395 | Q34: =P34*M34*G34 -> 15845.395 | R34: =(Q34+Q35+Q38+#REF!)/E12*1000 -> #REF! | S34: =Q34/$Q$51 -> 0.054921098 | T34: =Q34*2 -> 31690.791 | U34: =T34 -> 31690.791 | AA34: =T34 -> 31690.791 | AB34: =T34 -> 31690.791
A35: Manaus - AM | B35: Brasil Midia Exterior | C35: 50/156 | D35: Painel de Led | E35: Digital | F35: 6/12 | G35: 1 | H35: Mensal | I35: 1 | M35: 1 | N35: 7000 | O35: 0.1 | P35: =N35*(1-O35) -> 6300 | Q35: =P35*M35*G35 -> 6300 | S35: =Q35/$Q$51 -> 0.02183618 | T35: =Q35*2 -> 12600 | U35: =T35 -> 12600 | AA35: =T35 -> 12600 | AC35: =T35 -> 12600
A36: Manaus - AM | B36: Brasil Midia Exterior | C36: 50/156 | D36: Frontlight | E36: Estático | F36: 7/14 | G36: 1 | H36: Bisemanal | I36: 1 | M36: 1 | N36: 7500 | O36: 0.1 | P36: =N36*(1-O36) -> 6750 | Q36: =P36*M36*G36 -> 6750 | R36: =(Q36+#REF!)/E12*1000 -> #REF! | S36: =Q36/$Q$51 -> 0.023395908 | T36: =Q36*2 -> 13500 | U36: =T36 -> 13500 | Z36: =T36 -> 13500 | AC36: =T36 -> 13500
A37: Manaus - AM | B37: Brasil Midia Exterior | C37: 50/156 | D37: Outdoor lonado | E37: Estático | F37: 16/25 | G37: 20 | H37: Mensal | I37: 20 | M37: 1 | N37: 2900 | O37: 0.1 | P37: =N37*(1-O37) -> 2610 | Q37: =P37*M37*G37 -> 52200 | R37: =(Q37+#REF!)/E12*1000 -> #REF! | S37: =Q37/$Q$51 -> 0.18092835 | T37: =Q37*2 -> 104400 | U37: =T37 -> 104400 | Z37: =T37 -> 104400 | AC37: =T36 -> 13500
A38: Manaus - AM | B38: The Voice | C38: 50/156 | D38: Painel de Led | E38: Digital | F38: 6/12 | G38: 1 | H38: Mensal | I38: 1 | M38: 1 | N38: 17576 | O38: 0.55 | P38: =N38*(1-O38) -> 7909.2 | Q38: =P38*M38*G38 -> 7909.2 | S38: =Q38/$Q$51 -> 0.027413765 | T38: =Q38*2 -> 15818.4 | U38: =T38 -> 15818.4 | AA38: =T38 -> 15818.4 | AD38: =T37 -> 104400
A39: Manaus - AM | B39: VSP Midia | C39: 50/156 | D39: Frontlight | E39: Estático | F39: 7/14 | G39: 1 | H39: Mensal | I39: 1 | M39: 1 | N39: 5500 | O39: 0.15 | P39: =N39*(1-O39) -> 4675 | Q39: =P39*M39*G39 -> 4675 | R39: =(Q39+#REF!+Q40)/E12*1000 -> #REF! | S39: =Q39/$Q$51 -> 0.016203832 | T39: =Q39*2 -> 9350 | U39: =T39 -> 9350 | Z39: =T39 -> 9350 | AE39: =T39 -> 9350
A40: Manaus - AM | B40: WVK midias | C40: 50/156 | D40: Outdoor lonado | E40: Estática | F40: 16/25 | G40: 20 | H40: Mensal | K40: 20 | M40: 1 | N40: 3222.65 | O40: 0.2 | P40: =N40*(1-O40) -> 2578.12 | Q40: =P40*M40*G40 -> 51562.4 | S40: =Q40/$Q$51 -> 0.17871839 | T40: =Q40*2 -> 103124.8 | U40: =T40 -> 103124.8 | Z40: =T40 -> 103124.8 | AF40: =T40 -> 103124.8
A41: Manaus - AM | B41: Puraka | C41: 50/155 | D41: Painel de Led | E41: Digital | F41: 6/12 | G41: 5 | H41: Mensal | I41: 5 | M41: 1 | N41: 12150 | O41: 0.4 | P41: =N41*(1-O41) -> 7290 | Q41: =P41*M41*G41 -> 36450 | S41: =Q41/$Q$51 -> 0.1263379 | T41: =Q41*2 -> 72900 | U41: =T41 -> 72900 | AA41: =T41 -> 72900 | AG41: =T41 -> 72900
A42: Manaus - AM | B42: Puraka | C42: 50/155 | D42: Frontlight | E42: Estático | F42: 7/14 | G42: 4 | H42: Mensal | I42: 4 | M42: 1 | N42: 15000 | O42: 0.49 | P42: =N42*(1-O42) -> 7650 | Q42: =P42*M42*G42 -> 30600 | S42: =Q42/$Q$51 -> 0.10606145 | T42: =Q42*2 -> 61200 | U42: =T42 -> 61200 | Z42: =T42 -> 61200 | AG42: =T42 -> 61200
A43: Manaus - AM | B43: Bureau Midia OOH | C43: 50/155 | D43: Painel de Led | E43: Digital | F43: 6/12 | G43: 2 | H43: Mensal | I43: 2 | M43: 1 | N43: 8980 | O43: 0.25 | P43: =N43*(1-O43) -> 6735 | Q43: =P43*M43*G43 -> 13470 | S43: =Q43/$Q$51 -> 0.046687833 | T43: =Q43*2 -> 26940 | U43: =T43 -> 26940 | AA43: =T43 -> 26940 | AH43: =T43 -> 26940
A44: Manaus - AM | B44: Bureau Midia OOH | C44: 50/155 | D44: Frontlight | E44: Estático | F44: 7/14 | G44: 2 | H44: Mensal | I44: 2 | M44: 1 | N44: 14500 | O44: 0.25 | P44: =N44*(1-O44) -> 10875 | Q44: =P44*M44*G44 -> 21750 | S44: =Q44/$Q$51 -> 0.075386814 | T44: =Q44*2 -> 43500 | U44: =T44 -> 43500 | Z44: =T44 -> 43500 | AH44: =T44 -> 43500
A48: Manaus - AM | B48: Aeroporto | Q48: =P48*M48*G48 -> 0 | S48: =Q48/Q51 -> 0 | T48: =Q48*2 -> 0 | X48: =T48 -> 0 | AA48: =X48 -> 0
A49: Manaus - AM | B49: Oportunidades | Q49: 41000 | S49: =Q49/Q51 -> 0.14210848 | T49: =Q49*2 -> 82000 | Y49: =T49 -> 82000
I50: =I51/M51 -> 0.55555556 | K50: =K51/M51 -> 0.44444444
A51: Total faces compra | I51: =I39+I38+I37+I36+I35+I34 -> 25 | K51: =+K40 -> 20 | M51: =SUM(I51:L51) -> 45 | Q51: =SUM(Q34:Q50) -> 288512 | S51: =SUM(S34:S49) -> 1 | T51: =SUM(T34:T50) -> 577023.99 | U51: =SUM(U34:U49) -> 495023.99 | V51: =SUM(V34:V49) -> 0 | W51: =SUM(W34:W49) -> 0 | X51: =SUM(X34:X49) -> 0 | Y51: =SUM(Y34:Y49) -> 82000 | Z51: =SUM(Z34:Z49) -> 335074.8 | AA51: =SUM(AA34:AA49) -> 159949.19 | AB51: =SUM(AB34:AB50) -> 31690.791 | AC51: =SUM(AC34:AC50) -> 39600 | AD51: =SUM(AD34:AD50) -> 104400 | AE51: =SUM(AE34:AE50) -> 9350 | AF51: =SUM(AF34:AF50) -> 103124.8 | AG51: =SUM(AG34:AG50) -> 134100 | AH51: =SUM(AH34:AH50) -> 70440 | AI51: =SUM(AI33:AI50) -> 0
A52: Total faces simulação | I52: =I39+I38+I37+I36+I35+I34 -> 25 | J52: =I39+I38+I37+I36+I35+I34 -> 25 | K52: =+K40+I39+I38+I36+I35+I34 -> 25 | L52: =K40+I39+I38+I36+I35+I34 -> 25 | M52: =SUM(I52:L52) -> 100 | U52: =U51/T51 -> 0.85789152 | V52: =V51/T51 -> 0 | W52: =W51/T51 -> 0 | X52: =X51/T51 -> 0 | Y52: =Y51/T51 -> 0.14210848 | Z52: =Z51/T51 -> 0.58069475 | AA52: =AA51/T51 -> 0.27719678
A53: Grandes Formatos | I53: 0.25 | Q53: =U51/2 -> 247512 | S53: =Q53/Q58 -> 0.85789152 | Z53: =I36+I37+I39+K40 -> 42 | AA53: =I34+I35+I38 -> 3
...

Sheet MANAUS PLAN
A1: taxonomia | B1: regional_boticario | C1: uf | D1: praca | E1: exibidores | F1: formato | G1: ranking | H1: pesos | I1: estatico | J1: digital | K1: range_minimo | L1: range_maximo | M1: quantidade | N1: periodicidade | O1: s1 | P1: s2 | Q1: s3 | R1: s4 | S1: flight | T1: unitario_bruto_tabela | U1: desconto | V1: unitario_bruto_negociado | W1: total_bruto_negociado
A2: data produto | B2: norte | C2: am | D2: manaus | E2: WeOOH | F2: Painel de Led | G2: 2 | H2: =VLOOKUP(G2,Pesos!A:B,2,0) -> 0.8 | J2: x | K2: 2 | L2: 3 | M2: 2 | N2: Mensal | O2: 2 | Q2: 1 | S2: 1 | T2: 5200 | U2: 0.34 | V2: =T2*(1-U2) -> 3432 | W2: =V2*S2*M2 -> 6864
A3: data produto | B3: norte | C3: am | D3: manaus | E3: Brasil Midia Exterior | F3: Painel de Led | G3: 2 | H3: =VLOOKUP(G3,Pesos!A:B,2,0) -> 0.8 | J3: X | K3: 2 | L3: 4 | M3: 2 | N3: Mensal | O3: 2 | S3: 1 | T3: 7800 | U3: 0.34 | V3: =T3*(1-U3) -> 5148 | W3: =V3*S3*M3 -> 10296
A4: data produto | B4: norte | C4: am | D4: manaus | E4: Brasil Midia Exterior | F4: Frontlight | G4: 3 | H4: =VLOOKUP(G4,Pesos!A:B,2,0) -> 0.7 | I4: x | K4: 2 | L4: 4 | M4: 1 | N4: Mensal | O4: 1 | S4: 1 | T4: 3500 | U4: 0.2 | V4: =T4*(1-U4) -> 2800 | W4: =V4*S4*M4 -> 2800
A5: data produto | B5: norte | C5: am | D5: manaus | E5: Brasil Midia Exterior | F5: Outdoor lonado | G5: 1 | H5: =VLOOKUP(G5,Pesos!A:B,2,0) -> 0.9 | I5: X | K5: 10 | L5: 20 | M5: 15 | N5: Mensal | O5: 15 | S5: 1 | T5: 1500 | U5: 0.2 | V5: =T5*(1-U5) -> 1200 | W5: =V5*S5*M5 -> 18000
A6: data produto | B6: norte | C6: am | D6: manaus | E6: The Voice | F6: Painel de Led | G6: 2 | H6: =VLOOKUP(G6,Pesos!A:B,2,0) -> 0.8 | J6: x | K6: 10 | L6: 20 | M6: 15 | N6: Mensal | Q6: 15 | S6: 1 | T6: 1500 | U6: 0.2 | V6: =T6*(1-U6) -> 1200 | W6: =V6*S6*M6 -> 18000
A7: data produto | B7: norte | C7: am | D7: manaus | E7: VSP Midia | F7: Frontlight | G7: 3 | H7: =VLOOKUP(G7,Pesos!A:B,2,0) -> 0.7 | I7: x
A8: data produto | B8: norte | C8: am | D8: manaus | E8: WVK midias | F8: Outdoor lonado | G8: 1 | H8: =VLOOKUP(G8,Pesos!A:B,2,0) -> 0.9 | I8: x | K8: 2 | L8: 3 | M8: 1 | N8: Mensal | O8: 1 | S8: 1 | T8: 5200 | U8: 0.34 | V8: =T8*(1-U8) -> 3432 | W8: =V8*S8*M8 -> 3432
A9: data produto | B9: norte | C9: am | D9: manaus | E9: Puraka | F9: Painel de Led | G9: 2 | H9: =VLOOKUP(G9,Pesos!A:B,2,0) -> 0.8 | J9: x | K9: 2 | L9: 4 | M9: 1 | N9: Mensal | O9: 1 | S9: 1 | T9: 7800 | U9: 0.34 | V9: =T9*(1-U9) -> 5148 | W9: =V9*S9*M9 -> 5148
A10: data produto | B10: norte | C10: am | D10: manaus | E10: Puraka | F10: Frontlight | G10: 3 | H10: =VLOOKUP(G10,Pesos!A:B,2,0) -> 0.7 | I10: x | K10: 5 | L10: 10 | M10: 3 | N10: Mensal | O10: 3 | S10: 1 | T10: 1550 | U10: 0.2 | V10: =T10*(1-U10) -> 1240 | W10: =V10*S10*M10 -> 3720
A11: data produto | B11: norte | C11: am | D11: manaus | E11: Bureau Midia OOH | F11: Painel de Led | G11: 2 | H11: =VLOOKUP(G11,Pesos!A:B,2,0) -> 0.8 | J11: x | K11: 2 | L11: 5 | M11: 4 | N11: Diaria | O11: 4 | Q11: 4 | S11: 2 | T11: 2450 | U11: 0.2 | V11: =T11*(1-U11) -> 1960 | W11: =V11*S11*M11 -> 15680
A12: data produto | B12: norte | C12: am | D12: manaus | E12: Bureau Midia OOH | F12: Frontlight | G12: 3 | H12: =VLOOKUP(G12,Pesos!A:B,2,0) -> 0.7 | I12: x | K12: 2 | L12: 4 | M12: 1 | N12: Mensal | O12: 1 | S12: 1 | T12: 3500 | U12: 0.2 | V12: =T12*(1-U12) -> 2800 | W12: =V12*S12*M12 -> 2800
A14: data promo | B14: norte | C14: am | D14: manaus | E14: WeOOH | F14: Painel de Led | G14: 1 | H14: =VLOOKUP(G14,Pesos!A:B,2,0) -> 0.9 | J14: x | K14: 6 | L14: 12 | M14: 1 | N14: Mensal | O14: 1 | S14: 1 | T14: 35211.99 | U14: 0.55 | V14: =T14*(1-U14) -> 15845.395 | W14: =V14*S14*M14 -> 15845.395
A15: data promo | B15: norte | C15: am | D15: manaus | E15: Brasil Midia Exterior | F15: Painel de Led | G15: 1 | H15: =VLOOKUP(G15,Pesos!A:B,2,0) -> 0.9 | J15: x | K15: 6 | L15: 12 | M15: 1 | N15: Mensal | O15: 1 | S15: 1 | T15: 7000 | U15: 0.1 | V15: =T15*(1-U15) -> 6300 | W15: =V15*S15*M15 -> 6300
A16: data promo | B16: norte | C16: am | D16: manaus | E16: Brasil Midia Exterior | F16: Frontlight | G16: 4 | H16: =VLOOKUP(G16,Pesos!A:B,2,0) -> 0.6 | I16: x | K16: 7 | L16: 14 | M16: 1 | N16: Bisemanal | O16: 1 | S16: 1 | T16: 7500 | U16: 0.1 | V16: =T16*(1-U16) -> 6750 | W16: =V16*S16*M16 -> 6750
A17: data promo | B17: norte | C17: am | D17: manaus | E17: Brasil Midia Exterior | F17: Outdoor lonado | G17: 2 | H17: =VLOOKUP(G17,Pesos!A:B,2,0) -> 0.8 | I17: x | K17: 16 | L17: 25 | M17: 21 | N17: Mensal | O17: 20 | S17: 1 | T17: 2900 | U17: 0.1 | V17: =T17*(1-U17) -> 2610 | W17: =V17*S17*M17 -> 54810
A18: data promo | B18: norte | C18: am | D18: manaus | E18: The Voice | F18: Painel de Led | G18: 1 | H18: =VLOOKUP(G18,Pesos!A:B,2,0) -> 0.9 | J18: x | K18: 6 | L18: 12 | M18: 1 | N18: Mensal | O18: 1 | S18: 1 | T18: 17576 | U18: 0.55 | V18: =T18*(1-U18) -> 7909.2 | W18: =V18*S18*M18 -> 7909.2
